ply
format ascii 1.0
comment : MagicaVoxel @ Ephtracy
element vertex 10625
property float x
property float y
property float z
property uchar red
property uchar green
property uchar blue
end_header
-14 -6 1 110 85 47
-12 -6 1 110 85 47
-10 -6 1 110 85 47
-8 -6 1 110 85 47
-6 -6 1 110 85 47
-4 -6 1 110 85 47
-2 -6 1 110 85 47
0 -6 1 125 83 44
2 -6 1 125 83 44
-14 -5 1 125 83 44
-13 -5 1 125 83 44
-12 -5 1 125 83 44
-11 -5 1 125 83 44
-10 -5 1 125 83 44
-9 -5 1 125 83 44
-8 -5 1 125 83 44
-7 -5 1 125 83 44
-6 -5 1 125 83 44
-5 -5 1 125 83 44
-4 -5 1 125 83 44
-3 -5 1 125 83 44
-2 -5 1 125 83 44
-1 -5 1 125 83 44
0 -5 1 125 83 44
1 -5 1 125 83 44
2 -5 1 125 83 44
3 -5 1 125 83 44
-16 -4 1 189 192 186
-15 -4 1 189 192 186
-14 -4 1 189 192 186
-13 -4 1 189 192 186
-12 -4 1 189 192 186
-11 -4 1 189 192 186
-10 -4 1 189 192 186
-9 -4 1 189 192 186
-8 -4 1 189 192 186
-7 -4 1 189 192 186
-6 -4 1 189 192 186
-5 -4 1 189 192 186
-4 -4 1 189 192 186
-3 -4 1 189 192 186
-2 -4 1 189 192 186
-1 -4 1 189 192 186
0 -4 1 189 192 186
1 -4 1 189 192 186
2 -4 1 189 192 186
3 -4 1 125 83 44
4 -4 1 125 83 44
-16 -3 1 189 192 186
-15 -3 1 189 192 186
-14 -3 1 189 192 186
-13 -3 1 189 192 186
-12 -3 1 189 192 186
-11 -3 1 189 192 186
-10 -3 1 189 192 186
-9 -3 1 189 192 186
-8 -3 1 189 192 186
-7 -3 1 189 192 186
-6 -3 1 189 192 186
-5 -3 1 189 192 186
-4 -3 1 189 192 186
-3 -3 1 189 192 186
-2 -3 1 189 192 186
-1 -3 1 189 192 186
0 -3 1 189 192 186
1 -3 1 189 192 186
2 -3 1 189 192 186
3 -3 1 125 83 44
-16 -2 1 189 192 186
-15 -2 1 189 192 186
-14 -2 1 189 192 186
-13 -2 1 189 192 186
-12 -2 1 189 192 186
-11 -2 1 189 192 186
-10 -2 1 189 192 186
-9 -2 1 189 192 186
-8 -2 1 189 192 186
-7 -2 1 189 192 186
-6 -2 1 189 192 186
-5 -2 1 189 192 186
-4 -2 1 189 192 186
-3 -2 1 189 192 186
-2 -2 1 189 192 186
-1 -2 1 189 192 186
0 -2 1 189 192 186
1 -2 1 189 192 186
2 -2 1 189 192 186
3 -2 1 125 83 44
4 -2 1 125 83 44
-16 -1 1 189 192 186
-15 -1 1 189 192 186
-14 -1 1 189 192 186
-13 -1 1 189 192 186
-12 -1 1 189 192 186
-11 -1 1 189 192 186
-10 -1 1 189 192 186
-9 -1 1 189 192 186
-8 -1 1 189 192 186
-7 -1 1 189 192 186
-6 -1 1 189 192 186
-5 -1 1 189 192 186
-4 -1 1 189 192 186
-3 -1 1 189 192 186
-2 -1 1 189 192 186
-1 -1 1 189 192 186
0 -1 1 189 192 186
1 -1 1 189 192 186
2 -1 1 189 192 186
3 -1 1 125 83 44
-16 0 1 189 192 186
-15 0 1 189 192 186
-14 0 1 189 192 186
-13 0 1 189 192 186
-12 0 1 189 192 186
-11 0 1 189 192 186
-10 0 1 189 192 186
-9 0 1 189 192 186
-8 0 1 189 192 186
-7 0 1 189 192 186
-6 0 1 189 192 186
-5 0 1 189 192 186
-4 0 1 189 192 186
-3 0 1 189 192 186
-2 0 1 189 192 186
-1 0 1 189 192 186
0 0 1 189 192 186
1 0 1 189 192 186
2 0 1 189 192 186
3 0 1 125 83 44
4 0 1 125 83 44
-16 1 1 189 192 186
-15 1 1 189 192 186
-14 1 1 189 192 186
-13 1 1 189 192 186
-12 1 1 189 192 186
-11 1 1 189 192 186
-10 1 1 189 192 186
-9 1 1 189 192 186
-8 1 1 189 192 186
-7 1 1 189 192 186
-6 1 1 189 192 186
-5 1 1 189 192 186
-4 1 1 189 192 186
-3 1 1 189 192 186
-2 1 1 189 192 186
-1 1 1 189 192 186
0 1 1 189 192 186
1 1 1 189 192 186
2 1 1 189 192 186
3 1 1 125 83 44
-16 2 1 189 192 186
-15 2 1 189 192 186
-14 2 1 189 192 186
-13 2 1 189 192 186
-12 2 1 189 192 186
-11 2 1 189 192 186
-10 2 1 189 192 186
-9 2 1 189 192 186
-8 2 1 189 192 186
-7 2 1 189 192 186
-6 2 1 189 192 186
-5 2 1 189 192 186
-4 2 1 189 192 186
-3 2 1 189 192 186
-2 2 1 189 192 186
-1 2 1 189 192 186
0 2 1 189 192 186
1 2 1 189 192 186
2 2 1 189 192 186
3 2 1 125 83 44
4 2 1 125 83 44
-16 3 1 189 192 186
-15 3 1 189 192 186
-14 3 1 189 192 186
-13 3 1 189 192 186
-12 3 1 189 192 186
-11 3 1 189 192 186
-10 3 1 189 192 186
-9 3 1 189 192 186
-8 3 1 189 192 186
-7 3 1 189 192 186
-6 3 1 189 192 186
-5 3 1 189 192 186
-4 3 1 189 192 186
-3 3 1 189 192 186
-2 3 1 189 192 186
-1 3 1 189 192 186
0 3 1 189 192 186
1 3 1 189 192 186
2 3 1 189 192 186
3 3 1 125 83 44
-16 4 1 189 192 186
-15 4 1 189 192 186
-14 4 1 189 192 186
-13 4 1 189 192 186
-12 4 1 189 192 186
-11 4 1 189 192 186
-10 4 1 189 192 186
-9 4 1 189 192 186
-8 4 1 189 192 186
-7 4 1 189 192 186
-6 4 1 189 192 186
-5 4 1 189 192 186
-4 4 1 189 192 186
-3 4 1 189 192 186
-2 4 1 189 192 186
-1 4 1 189 192 186
0 4 1 189 192 186
1 4 1 189 192 186
2 4 1 189 192 186
3 4 1 125 83 44
4 4 1 125 83 44
-16 5 1 189 192 186
-15 5 1 189 192 186
-14 5 1 189 192 186
-13 5 1 189 192 186
-12 5 1 189 192 186
-11 5 1 189 192 186
-10 5 1 189 192 186
-9 5 1 189 192 186
-8 5 1 189 192 186
-7 5 1 189 192 186
-6 5 1 189 192 186
-5 5 1 189 192 186
-4 5 1 189 192 186
-3 5 1 189 192 186
-2 5 1 189 192 186
-1 5 1 189 192 186
0 5 1 189 192 186
1 5 1 189 192 186
2 5 1 189 192 186
3 5 1 125 83 44
-16 6 1 189 192 186
-15 6 1 189 192 186
-14 6 1 189 192 186
-13 6 1 189 192 186
-12 6 1 189 192 186
-11 6 1 189 192 186
-10 6 1 189 192 186
-9 6 1 189 192 186
-8 6 1 189 192 186
-7 6 1 189 192 186
-6 6 1 189 192 186
-5 6 1 189 192 186
-4 6 1 189 192 186
-3 6 1 189 192 186
-2 6 1 189 192 186
-1 6 1 189 192 186
0 6 1 189 192 186
1 6 1 189 192 186
2 6 1 189 192 186
-16 7 1 189 192 186
-15 7 1 189 192 186
-14 7 1 189 192 186
-13 7 1 189 192 186
-12 7 1 189 192 186
-11 7 1 189 192 186
-10 7 1 189 192 186
-9 7 1 189 192 186
-8 7 1 189 192 186
-7 7 1 189 192 186
-6 7 1 189 192 186
-5 7 1 189 192 186
-4 7 1 189 192 186
-3 7 1 189 192 186
-2 7 1 189 192 186
-1 7 1 189 192 186
0 7 1 189 192 186
1 7 1 189 192 186
2 7 1 189 192 186
3 7 1 105 176 172
4 7 1 105 176 172
5 7 1 105 176 172
6 7 1 105 176 172
-16 8 1 189 192 186
-15 8 1 189 192 186
-14 8 1 189 192 186
-13 8 1 189 192 186
-12 8 1 189 192 186
-11 8 1 189 192 186
-10 8 1 189 192 186
-9 8 1 189 192 186
-8 8 1 189 192 186
-7 8 1 189 192 186
-6 8 1 189 192 186
-5 8 1 189 192 186
-4 8 1 189 192 186
-3 8 1 189 192 186
-2 8 1 189 192 186
-1 8 1 189 192 186
0 8 1 189 192 186
1 8 1 189 192 186
2 8 1 189 192 186
3 8 1 105 176 172
4 8 1 105 176 172
5 8 1 105 176 172
6 8 1 105 176 172
-16 9 1 189 192 186
-15 9 1 189 192 186
-14 9 1 189 192 186
-13 9 1 189 192 186
-12 9 1 189 192 186
-11 9 1 189 192 186
-10 9 1 189 192 186
-9 9 1 189 192 186
-8 9 1 189 192 186
-7 9 1 189 192 186
-6 9 1 189 192 186
-5 9 1 189 192 186
-4 9 1 189 192 186
-3 9 1 189 192 186
-2 9 1 189 192 186
-1 9 1 189 192 186
0 9 1 189 192 186
1 9 1 189 192 186
2 9 1 189 192 186
3 9 1 105 176 172
4 9 1 105 176 172
5 9 1 105 176 172
6 9 1 105 176 172
-16 10 1 189 192 186
-15 10 1 189 192 186
-14 10 1 189 192 186
-13 10 1 189 192 186
-12 10 1 189 192 186
-11 10 1 189 192 186
-10 10 1 189 192 186
-9 10 1 189 192 186
-8 10 1 189 192 186
-7 10 1 189 192 186
-6 10 1 189 192 186
-5 10 1 189 192 186
-4 10 1 189 192 186
-3 10 1 189 192 186
-2 10 1 189 192 186
-1 10 1 189 192 186
0 10 1 189 192 186
1 10 1 189 192 186
2 10 1 189 192 186
3 10 1 105 176 172
4 10 1 105 176 172
5 10 1 105 176 172
6 10 1 105 176 172
-16 11 1 189 192 186
-15 11 1 189 192 186
-14 11 1 189 192 186
-13 11 1 189 192 186
-12 11 1 189 192 186
-11 11 1 189 192 186
-10 11 1 189 192 186
-9 11 1 189 192 186
-8 11 1 189 192 186
-7 11 1 189 192 186
-6 11 1 189 192 186
-5 11 1 189 192 186
-4 11 1 189 192 186
-3 11 1 189 192 186
-2 11 1 189 192 186
-1 11 1 189 192 186
0 11 1 189 192 186
1 11 1 189 192 186
2 11 1 189 192 186
3 11 1 105 176 172
4 11 1 105 176 172
5 11 1 105 176 172
6 11 1 105 176 172
-16 12 1 189 192 186
-15 12 1 189 192 186
-14 12 1 189 192 186
-13 12 1 189 192 186
-12 12 1 189 192 186
-11 12 1 189 192 186
-10 12 1 189 192 186
-9 12 1 189 192 186
-8 12 1 189 192 186
-7 12 1 189 192 186
-6 12 1 189 192 186
-5 12 1 189 192 186
-4 12 1 189 192 186
-3 12 1 189 192 186
-2 12 1 189 192 186
-1 12 1 189 192 186
0 12 1 189 192 186
1 12 1 189 192 186
2 12 1 189 192 186
3 12 1 105 176 172
4 12 1 105 176 172
5 12 1 105 176 172
6 12 1 105 176 172
-16 13 1 189 192 186
-15 13 1 189 192 186
-14 13 1 189 192 186
-13 13 1 189 192 186
-12 13 1 189 192 186
-11 13 1 189 192 186
-10 13 1 189 192 186
-9 13 1 189 192 186
-8 13 1 189 192 186
-7 13 1 189 192 186
-6 13 1 189 192 186
-5 13 1 189 192 186
-4 13 1 189 192 186
-3 13 1 189 192 186
-2 13 1 189 192 186
-1 13 1 189 192 186
0 13 1 189 192 186
1 13 1 189 192 186
2 13 1 189 192 186
3 13 1 105 176 172
4 13 1 105 176 172
5 13 1 105 176 172
6 13 1 105 176 172
-16 14 1 189 192 186
-15 14 1 189 192 186
-14 14 1 189 192 186
-13 14 1 189 192 186
-12 14 1 189 192 186
-11 14 1 189 192 186
-10 14 1 189 192 186
-9 14 1 189 192 186
-8 14 1 189 192 186
-7 14 1 189 192 186
-6 14 1 189 192 186
-5 14 1 189 192 186
-4 14 1 189 192 186
-3 14 1 189 192 186
-2 14 1 189 192 186
-1 14 1 189 192 186
0 14 1 189 192 186
1 14 1 189 192 186
2 14 1 189 192 186
-16 15 1 189 192 186
-15 15 1 189 192 186
-14 15 1 189 192 186
-13 15 1 189 192 186
-12 15 1 189 192 186
-11 15 1 189 192 186
-10 15 1 189 192 186
-9 15 1 189 192 186
-8 15 1 189 192 186
-7 15 1 189 192 186
-6 15 1 189 192 186
-5 15 1 189 192 186
-4 15 1 189 192 186
-3 15 1 189 192 186
-2 15 1 189 192 186
-1 15 1 189 192 186
0 15 1 189 192 186
1 15 1 189 192 186
2 15 1 189 192 186
-16 16 1 189 192 186
-15 16 1 189 192 186
-14 16 1 189 192 186
-13 16 1 189 192 186
-12 16 1 189 192 186
-11 16 1 189 192 186
-10 16 1 189 192 186
-9 16 1 189 192 186
-8 16 1 189 192 186
-7 16 1 189 192 186
-6 16 1 189 192 186
-5 16 1 189 192 186
-4 16 1 189 192 186
-3 16 1 189 192 186
-2 16 1 189 192 186
-1 16 1 189 192 186
0 16 1 189 192 186
1 16 1 189 192 186
2 16 1 189 192 186
-16 17 1 189 192 186
-15 17 1 189 192 186
-14 17 1 189 192 186
-13 17 1 189 192 186
-12 17 1 189 192 186
-11 17 1 189 192 186
-10 17 1 189 192 186
-9 17 1 189 192 186
-8 17 1 189 192 186
-7 17 1 189 192 186
-6 17 1 189 192 186
-5 17 1 189 192 186
-4 17 1 189 192 186
-3 17 1 189 192 186
-2 17 1 189 192 186
-1 17 1 189 192 186
0 17 1 189 192 186
1 17 1 189 192 186
2 17 1 189 192 186
-16 18 1 189 192 186
-15 18 1 189 192 186
-14 18 1 189 192 186
-13 18 1 189 192 186
-12 18 1 189 192 186
-11 18 1 189 192 186
-10 18 1 189 192 186
-9 18 1 189 192 186
-8 18 1 189 192 186
-7 18 1 189 192 186
-6 18 1 189 192 186
-5 18 1 189 192 186
-4 18 1 189 192 186
-3 18 1 189 192 186
-2 18 1 189 192 186
-1 18 1 189 192 186
0 18 1 189 192 186
1 18 1 189 192 186
2 18 1 189 192 186
-16 19 1 189 192 186
-15 19 1 189 192 186
-14 19 1 189 192 186
-13 19 1 189 192 186
-12 19 1 189 192 186
-11 19 1 189 192 186
-10 19 1 189 192 186
-9 19 1 189 192 186
-8 19 1 189 192 186
-7 19 1 189 192 186
-6 19 1 189 192 186
-5 19 1 189 192 186
-4 19 1 189 192 186
-3 19 1 189 192 186
-2 19 1 189 192 186
-1 19 1 189 192 186
0 19 1 189 192 186
1 19 1 189 192 186
2 19 1 189 192 186
-14 -6 2 110 85 47
-12 -6 2 110 85 47
-10 -6 2 110 85 47
-8 -6 2 110 85 47
-6 -6 2 110 85 47
-4 -6 2 110 85 47
-2 -6 2 110 85 47
0 -6 2 125 83 44
2 -6 2 125 83 44
-14 -5 2 125 83 44
-13 -5 2 125 83 44
-12 -5 2 125 83 44
-11 -5 2 125 83 44
-10 -5 2 125 83 44
-9 -5 2 125 83 44
-8 -5 2 125 83 44
-7 -5 2 125 83 44
-6 -5 2 125 83 44
-5 -5 2 125 83 44
-4 -5 2 125 83 44
-3 -5 2 125 83 44
-2 -5 2 125 83 44
-1 -5 2 125 83 44
0 -5 2 125 83 44
1 -5 2 125 83 44
2 -5 2 125 83 44
3 -5 2 125 83 44
-16 -4 2 189 192 186
-15 -4 2 189 192 186
-14 -4 2 189 192 186
-13 -4 2 189 192 186
-12 -4 2 189 192 186
-11 -4 2 189 192 186
-10 -4 2 189 192 186
-9 -4 2 189 192 186
-8 -4 2 189 192 186
-7 -4 2 189 192 186
-6 -4 2 189 192 186
-5 -4 2 189 192 186
-4 -4 2 189 192 186
-3 -4 2 189 192 186
-2 -4 2 189 192 186
-1 -4 2 189 192 186
0 -4 2 189 192 186
1 -4 2 189 192 186
2 -4 2 189 192 186
3 -4 2 125 83 44
4 -4 2 125 83 44
-16 -3 2 189 192 186
-15 -3 2 189 192 186
-14 -3 2 189 192 186
-13 -3 2 189 192 186
-12 -3 2 189 192 186
-11 -3 2 189 192 186
-10 -3 2 189 192 186
-9 -3 2 189 192 186
-8 -3 2 189 192 186
-7 -3 2 189 192 186
-6 -3 2 189 192 186
-5 -3 2 189 192 186
-4 -3 2 189 192 186
-3 -3 2 189 192 186
-2 -3 2 189 192 186
-1 -3 2 189 192 186
0 -3 2 189 192 186
1 -3 2 189 192 186
2 -3 2 189 192 186
3 -3 2 125 83 44
-16 -2 2 189 192 186
-15 -2 2 189 192 186
-14 -2 2 189 192 186
-13 -2 2 189 192 186
-12 -2 2 189 192 186
-11 -2 2 189 192 186
-10 -2 2 189 192 186
-9 -2 2 189 192 186
-8 -2 2 189 192 186
-7 -2 2 189 192 186
-6 -2 2 189 192 186
-5 -2 2 189 192 186
-4 -2 2 189 192 186
-3 -2 2 189 192 186
-2 -2 2 189 192 186
-1 -2 2 189 192 186
0 -2 2 189 192 186
1 -2 2 189 192 186
2 -2 2 189 192 186
3 -2 2 125 83 44
4 -2 2 125 83 44
-16 -1 2 189 192 186
-15 -1 2 189 192 186
-14 -1 2 189 192 186
-13 -1 2 189 192 186
-12 -1 2 189 192 186
-11 -1 2 189 192 186
-10 -1 2 189 192 186
-9 -1 2 189 192 186
-8 -1 2 189 192 186
-7 -1 2 189 192 186
-6 -1 2 189 192 186
-5 -1 2 189 192 186
-4 -1 2 189 192 186
-3 -1 2 189 192 186
-2 -1 2 189 192 186
-1 -1 2 189 192 186
0 -1 2 189 192 186
1 -1 2 189 192 186
2 -1 2 189 192 186
3 -1 2 125 83 44
-16 0 2 189 192 186
-15 0 2 189 192 186
-14 0 2 189 192 186
-13 0 2 189 192 186
-12 0 2 189 192 186
-11 0 2 189 192 186
-10 0 2 189 192 186
-9 0 2 189 192 186
-8 0 2 189 192 186
-7 0 2 189 192 186
-6 0 2 189 192 186
-5 0 2 189 192 186
-4 0 2 189 192 186
-3 0 2 189 192 186
-2 0 2 189 192 186
-1 0 2 189 192 186
0 0 2 189 192 186
1 0 2 189 192 186
2 0 2 189 192 186
3 0 2 125 83 44
4 0 2 125 83 44
-16 1 2 189 192 186
-15 1 2 189 192 186
-14 1 2 189 192 186
-13 1 2 189 192 186
-12 1 2 189 192 186
-11 1 2 189 192 186
-10 1 2 189 192 186
-9 1 2 189 192 186
-8 1 2 189 192 186
-7 1 2 189 192 186
-6 1 2 189 192 186
-5 1 2 189 192 186
-4 1 2 189 192 186
-3 1 2 189 192 186
-2 1 2 189 192 186
-1 1 2 189 192 186
0 1 2 189 192 186
1 1 2 189 192 186
2 1 2 189 192 186
3 1 2 125 83 44
-16 2 2 189 192 186
-15 2 2 189 192 186
-14 2 2 189 192 186
-13 2 2 189 192 186
-12 2 2 189 192 186
-11 2 2 189 192 186
-10 2 2 189 192 186
-9 2 2 189 192 186
-8 2 2 189 192 186
-7 2 2 189 192 186
-6 2 2 189 192 186
-5 2 2 189 192 186
-4 2 2 189 192 186
-3 2 2 189 192 186
-2 2 2 189 192 186
-1 2 2 189 192 186
0 2 2 189 192 186
1 2 2 189 192 186
2 2 2 189 192 186
3 2 2 125 83 44
4 2 2 125 83 44
-16 3 2 189 192 186
-15 3 2 189 192 186
-14 3 2 189 192 186
-13 3 2 189 192 186
-12 3 2 189 192 186
-11 3 2 189 192 186
-10 3 2 189 192 186
-9 3 2 189 192 186
-8 3 2 189 192 186
-7 3 2 189 192 186
-6 3 2 189 192 186
-5 3 2 189 192 186
-4 3 2 189 192 186
-3 3 2 189 192 186
-2 3 2 189 192 186
-1 3 2 189 192 186
0 3 2 189 192 186
1 3 2 189 192 186
2 3 2 189 192 186
3 3 2 125 83 44
-16 4 2 189 192 186
-15 4 2 189 192 186
-14 4 2 189 192 186
-13 4 2 189 192 186
-12 4 2 189 192 186
-11 4 2 189 192 186
-10 4 2 189 192 186
-9 4 2 189 192 186
-8 4 2 189 192 186
-7 4 2 189 192 186
-6 4 2 189 192 186
-5 4 2 189 192 186
-4 4 2 189 192 186
-3 4 2 189 192 186
-2 4 2 189 192 186
-1 4 2 189 192 186
0 4 2 189 192 186
1 4 2 189 192 186
2 4 2 189 192 186
3 4 2 125 83 44
4 4 2 125 83 44
-16 5 2 189 192 186
-15 5 2 189 192 186
-14 5 2 189 192 186
-13 5 2 189 192 186
-12 5 2 189 192 186
-11 5 2 189 192 186
-10 5 2 189 192 186
-9 5 2 189 192 186
-8 5 2 189 192 186
-7 5 2 189 192 186
-6 5 2 189 192 186
-5 5 2 189 192 186
-4 5 2 189 192 186
-3 5 2 189 192 186
-2 5 2 189 192 186
-1 5 2 189 192 186
0 5 2 189 192 186
1 5 2 189 192 186
2 5 2 189 192 186
3 5 2 125 83 44
-16 6 2 189 192 186
-15 6 2 189 192 186
-14 6 2 189 192 186
-13 6 2 189 192 186
-12 6 2 189 192 186
-11 6 2 189 192 186
-10 6 2 189 192 186
-9 6 2 189 192 186
-8 6 2 189 192 186
-7 6 2 189 192 186
-6 6 2 189 192 186
-5 6 2 189 192 186
-4 6 2 189 192 186
-3 6 2 189 192 186
-2 6 2 189 192 186
-1 6 2 189 192 186
0 6 2 189 192 186
1 6 2 189 192 186
2 6 2 189 192 186
-16 7 2 189 192 186
-15 7 2 189 192 186
-14 7 2 189 192 186
-13 7 2 189 192 186
-12 7 2 189 192 186
-11 7 2 189 192 186
-10 7 2 189 192 186
-9 7 2 189 192 186
-8 7 2 189 192 186
-7 7 2 189 192 186
-6 7 2 189 192 186
-5 7 2 189 192 186
-4 7 2 189 192 186
-3 7 2 189 192 186
-2 7 2 189 192 186
-1 7 2 189 192 186
0 7 2 189 192 186
1 7 2 189 192 186
2 7 2 189 192 186
3 7 2 105 176 172
4 7 2 105 176 172
5 7 2 105 176 172
6 7 2 105 176 172
-16 8 2 189 192 186
-15 8 2 189 192 186
-14 8 2 189 192 186
-13 8 2 189 192 186
-12 8 2 189 192 186
-11 8 2 189 192 186
-10 8 2 189 192 186
-9 8 2 189 192 186
-8 8 2 189 192 186
-7 8 2 189 192 186
-6 8 2 189 192 186
-5 8 2 189 192 186
-4 8 2 189 192 186
-3 8 2 189 192 186
-2 8 2 189 192 186
-1 8 2 189 192 186
0 8 2 189 192 186
1 8 2 189 192 186
2 8 2 189 192 186
3 8 2 105 176 172
4 8 2 105 176 172
5 8 2 105 176 172
6 8 2 105 176 172
-16 9 2 189 192 186
-15 9 2 189 192 186
-14 9 2 189 192 186
-13 9 2 189 192 186
-12 9 2 189 192 186
-11 9 2 189 192 186
-10 9 2 189 192 186
-9 9 2 189 192 186
-8 9 2 189 192 186
-7 9 2 189 192 186
-6 9 2 189 192 186
-5 9 2 189 192 186
-4 9 2 189 192 186
-3 9 2 189 192 186
-2 9 2 189 192 186
-1 9 2 189 192 186
0 9 2 189 192 186
1 9 2 189 192 186
2 9 2 189 192 186
3 9 2 105 176 172
4 9 2 105 176 172
5 9 2 255 255 251
-16 10 2 189 192 186
-15 10 2 189 192 186
-14 10 2 189 192 186
-13 10 2 189 192 186
-12 10 2 189 192 186
-11 10 2 189 192 186
-10 10 2 189 192 186
-9 10 2 189 192 186
-8 10 2 189 192 186
-7 10 2 189 192 186
-6 10 2 189 192 186
-5 10 2 189 192 186
-4 10 2 189 192 186
-3 10 2 189 192 186
-2 10 2 189 192 186
-1 10 2 189 192 186
0 10 2 189 192 186
1 10 2 189 192 186
2 10 2 189 192 186
3 10 2 105 176 172
4 10 2 105 176 172
5 10 2 255 255 251
-16 11 2 189 192 186
-15 11 2 189 192 186
-14 11 2 189 192 186
-13 11 2 189 192 186
-12 11 2 189 192 186
-11 11 2 189 192 186
-10 11 2 189 192 186
-9 11 2 189 192 186
-8 11 2 189 192 186
-7 11 2 189 192 186
-6 11 2 189 192 186
-5 11 2 189 192 186
-4 11 2 189 192 186
-3 11 2 189 192 186
-2 11 2 189 192 186
-1 11 2 189 192 186
0 11 2 189 192 186
1 11 2 189 192 186
2 11 2 189 192 186
3 11 2 105 176 172
4 11 2 105 176 172
5 11 2 255 255 251
-16 12 2 189 192 186
-15 12 2 189 192 186
-14 12 2 189 192 186
-13 12 2 189 192 186
-12 12 2 189 192 186
-11 12 2 189 192 186
-10 12 2 189 192 186
-9 12 2 189 192 186
-8 12 2 189 192 186
-7 12 2 189 192 186
-6 12 2 189 192 186
-5 12 2 189 192 186
-4 12 2 189 192 186
-3 12 2 189 192 186
-2 12 2 189 192 186
-1 12 2 189 192 186
0 12 2 189 192 186
1 12 2 189 192 186
2 12 2 189 192 186
3 12 2 105 176 172
4 12 2 105 176 172
5 12 2 105 176 172
6 12 2 105 176 172
-16 13 2 189 192 186
-15 13 2 189 192 186
-14 13 2 189 192 186
-13 13 2 189 192 186
-12 13 2 189 192 186
-11 13 2 189 192 186
-10 13 2 189 192 186
-9 13 2 189 192 186
-8 13 2 189 192 186
-7 13 2 189 192 186
-6 13 2 189 192 186
-5 13 2 189 192 186
-4 13 2 189 192 186
-3 13 2 189 192 186
-2 13 2 189 192 186
-1 13 2 189 192 186
0 13 2 189 192 186
1 13 2 189 192 186
2 13 2 189 192 186
3 13 2 105 176 172
4 13 2 105 176 172
5 13 2 105 176 172
6 13 2 105 176 172
-16 14 2 189 192 186
-15 14 2 189 192 186
-14 14 2 189 192 186
-13 14 2 189 192 186
-12 14 2 189 192 186
-11 14 2 189 192 186
-10 14 2 189 192 186
-9 14 2 189 192 186
-8 14 2 189 192 186
-7 14 2 189 192 186
-6 14 2 189 192 186
-5 14 2 189 192 186
-4 14 2 189 192 186
-3 14 2 189 192 186
-2 14 2 189 192 186
-1 14 2 189 192 186
0 14 2 189 192 186
1 14 2 189 192 186
2 14 2 189 192 186
-16 15 2 189 192 186
-15 15 2 189 192 186
-14 15 2 189 192 186
-13 15 2 189 192 186
-12 15 2 189 192 186
-11 15 2 189 192 186
-10 15 2 189 192 186
-9 15 2 189 192 186
-8 15 2 189 192 186
-7 15 2 189 192 186
-6 15 2 189 192 186
-5 15 2 189 192 186
-4 15 2 189 192 186
-3 15 2 189 192 186
-2 15 2 189 192 186
-1 15 2 189 192 186
0 15 2 189 192 186
1 15 2 189 192 186
2 15 2 189 192 186
-16 16 2 189 192 186
-15 16 2 189 192 186
-14 16 2 189 192 186
-13 16 2 189 192 186
-12 16 2 189 192 186
-11 16 2 189 192 186
-10 16 2 189 192 186
-9 16 2 189 192 186
-8 16 2 189 192 186
-7 16 2 189 192 186
-6 16 2 189 192 186
-5 16 2 189 192 186
-4 16 2 189 192 186
-3 16 2 189 192 186
-2 16 2 189 192 186
-1 16 2 189 192 186
0 16 2 189 192 186
1 16 2 189 192 186
2 16 2 189 192 186
-16 17 2 189 192 186
-15 17 2 189 192 186
-14 17 2 189 192 186
-13 17 2 189 192 186
-12 17 2 189 192 186
-11 17 2 189 192 186
-10 17 2 189 192 186
-9 17 2 189 192 186
-8 17 2 189 192 186
-7 17 2 189 192 186
-6 17 2 189 192 186
-5 17 2 189 192 186
-4 17 2 189 192 186
-3 17 2 189 192 186
-2 17 2 189 192 186
-1 17 2 189 192 186
0 17 2 189 192 186
1 17 2 189 192 186
2 17 2 189 192 186
-16 18 2 189 192 186
-15 18 2 189 192 186
-14 18 2 189 192 186
-13 18 2 189 192 186
-12 18 2 189 192 186
-11 18 2 189 192 186
-10 18 2 189 192 186
-9 18 2 189 192 186
-8 18 2 189 192 186
-7 18 2 189 192 186
-6 18 2 189 192 186
-5 18 2 189 192 186
-4 18 2 189 192 186
-3 18 2 189 192 186
-2 18 2 189 192 186
-1 18 2 189 192 186
0 18 2 189 192 186
1 18 2 189 192 186
2 18 2 189 192 186
-16 19 2 189 192 186
-15 19 2 189 192 186
-14 19 2 189 192 186
-13 19 2 189 192 186
-12 19 2 189 192 186
-11 19 2 189 192 186
-10 19 2 189 192 186
-9 19 2 189 192 186
-8 19 2 189 192 186
-7 19 2 189 192 186
-6 19 2 189 192 186
-5 19 2 189 192 186
-4 19 2 189 192 186
-3 19 2 189 192 186
-2 19 2 189 192 186
-1 19 2 189 192 186
0 19 2 189 192 186
1 19 2 189 192 186
2 19 2 189 192 186
-14 -6 3 110 85 47
-12 -6 3 110 85 47
-10 -6 3 110 85 47
-8 -6 3 110 85 47
-6 -6 3 110 85 47
-4 -6 3 110 85 47
-2 -6 3 110 85 47
0 -6 3 125 83 44
2 -6 3 125 83 44
-14 -5 3 125 83 44
-13 -5 3 125 83 44
-12 -5 3 125 83 44
-11 -5 3 125 83 44
-10 -5 3 125 83 44
-9 -5 3 125 83 44
-8 -5 3 125 83 44
-7 -5 3 125 83 44
-6 -5 3 125 83 44
-5 -5 3 125 83 44
-4 -5 3 125 83 44
-3 -5 3 125 83 44
-2 -5 3 125 83 44
-1 -5 3 125 83 44
0 -5 3 125 83 44
1 -5 3 125 83 44
2 -5 3 125 83 44
3 -5 3 125 83 44
-16 -4 3 189 192 186
-15 -4 3 189 192 186
-14 -4 3 189 192 186
-13 -4 3 189 192 186
-12 -4 3 189 192 186
-11 -4 3 189 192 186
-10 -4 3 189 192 186
-9 -4 3 189 192 186
-8 -4 3 189 192 186
-7 -4 3 189 192 186
-6 -4 3 189 192 186
-5 -4 3 189 192 186
-4 -4 3 189 192 186
-3 -4 3 189 192 186
-2 -4 3 189 192 186
-1 -4 3 189 192 186
0 -4 3 189 192 186
1 -4 3 189 192 186
2 -4 3 189 192 186
3 -4 3 125 83 44
4 -4 3 125 83 44
-16 -3 3 189 192 186
-15 -3 3 189 192 186
-14 -3 3 189 192 186
-13 -3 3 189 192 186
-12 -3 3 189 192 186
-11 -3 3 189 192 186
-10 -3 3 189 192 186
-9 -3 3 189 192 186
-8 -3 3 189 192 186
-7 -3 3 189 192 186
-6 -3 3 189 192 186
-5 -3 3 189 192 186
-4 -3 3 189 192 186
-3 -3 3 189 192 186
-2 -3 3 189 192 186
-1 -3 3 189 192 186
0 -3 3 189 192 186
1 -3 3 189 192 186
2 -3 3 189 192 186
3 -3 3 125 83 44
-16 -2 3 189 192 186
-15 -2 3 189 192 186
-14 -2 3 189 192 186
-13 -2 3 189 192 186
-12 -2 3 189 192 186
-11 -2 3 189 192 186
-10 -2 3 189 192 186
-9 -2 3 189 192 186
-8 -2 3 189 192 186
-7 -2 3 189 192 186
-6 -2 3 189 192 186
-5 -2 3 189 192 186
-4 -2 3 189 192 186
-3 -2 3 189 192 186
-2 -2 3 189 192 186
-1 -2 3 189 192 186
0 -2 3 189 192 186
1 -2 3 189 192 186
2 -2 3 189 192 186
3 -2 3 125 83 44
4 -2 3 125 83 44
-16 -1 3 189 192 186
-15 -1 3 189 192 186
-14 -1 3 189 192 186
-13 -1 3 189 192 186
-12 -1 3 189 192 186
-11 -1 3 189 192 186
-10 -1 3 189 192 186
-9 -1 3 189 192 186
-8 -1 3 189 192 186
-7 -1 3 189 192 186
-6 -1 3 189 192 186
-5 -1 3 189 192 186
-4 -1 3 189 192 186
-3 -1 3 189 192 186
-2 -1 3 189 192 186
-1 -1 3 189 192 186
0 -1 3 189 192 186
1 -1 3 189 192 186
2 -1 3 189 192 186
3 -1 3 125 83 44
-16 0 3 189 192 186
-15 0 3 189 192 186
-14 0 3 189 192 186
-13 0 3 189 192 186
-12 0 3 189 192 186
-11 0 3 189 192 186
-10 0 3 189 192 186
-9 0 3 189 192 186
-8 0 3 189 192 186
-7 0 3 189 192 186
-6 0 3 189 192 186
-5 0 3 189 192 186
-4 0 3 189 192 186
-3 0 3 189 192 186
-2 0 3 189 192 186
-1 0 3 189 192 186
0 0 3 189 192 186
1 0 3 189 192 186
2 0 3 189 192 186
3 0 3 125 83 44
4 0 3 125 83 44
-16 1 3 189 192 186
-15 1 3 189 192 186
-14 1 3 189 192 186
-13 1 3 189 192 186
-12 1 3 189 192 186
-11 1 3 189 192 186
-10 1 3 189 192 186
-9 1 3 189 192 186
-8 1 3 189 192 186
-7 1 3 189 192 186
-6 1 3 189 192 186
-5 1 3 189 192 186
-4 1 3 189 192 186
-3 1 3 189 192 186
-2 1 3 189 192 186
-1 1 3 189 192 186
0 1 3 189 192 186
1 1 3 189 192 186
2 1 3 189 192 186
3 1 3 125 83 44
-16 2 3 189 192 186
-15 2 3 189 192 186
-14 2 3 189 192 186
-13 2 3 189 192 186
-12 2 3 189 192 186
-11 2 3 189 192 186
-10 2 3 189 192 186
-9 2 3 189 192 186
-8 2 3 189 192 186
-7 2 3 189 192 186
-6 2 3 189 192 186
-5 2 3 189 192 186
-4 2 3 189 192 186
-3 2 3 189 192 186
-2 2 3 189 192 186
-1 2 3 189 192 186
0 2 3 189 192 186
1 2 3 189 192 186
2 2 3 189 192 186
3 2 3 125 83 44
4 2 3 125 83 44
-16 3 3 189 192 186
-15 3 3 189 192 186
-14 3 3 189 192 186
-13 3 3 189 192 186
-12 3 3 189 192 186
-11 3 3 189 192 186
-10 3 3 189 192 186
-9 3 3 189 192 186
-8 3 3 189 192 186
-7 3 3 189 192 186
-6 3 3 189 192 186
-5 3 3 189 192 186
-4 3 3 189 192 186
-3 3 3 189 192 186
-2 3 3 189 192 186
-1 3 3 189 192 186
0 3 3 189 192 186
1 3 3 189 192 186
2 3 3 189 192 186
3 3 3 125 83 44
-16 4 3 189 192 186
-15 4 3 189 192 186
-14 4 3 189 192 186
-13 4 3 189 192 186
-12 4 3 189 192 186
-11 4 3 189 192 186
-10 4 3 189 192 186
-9 4 3 189 192 186
-8 4 3 189 192 186
-7 4 3 189 192 186
-6 4 3 189 192 186
-5 4 3 189 192 186
-4 4 3 189 192 186
-3 4 3 189 192 186
-2 4 3 189 192 186
-1 4 3 189 192 186
0 4 3 189 192 186
1 4 3 189 192 186
2 4 3 189 192 186
3 4 3 125 83 44
4 4 3 125 83 44
-16 5 3 189 192 186
-15 5 3 189 192 186
-14 5 3 189 192 186
-13 5 3 189 192 186
-12 5 3 189 192 186
-11 5 3 189 192 186
-10 5 3 189 192 186
-9 5 3 189 192 186
-8 5 3 189 192 186
-7 5 3 189 192 186
-6 5 3 189 192 186
-5 5 3 189 192 186
-4 5 3 189 192 186
-3 5 3 189 192 186
-2 5 3 189 192 186
-1 5 3 189 192 186
0 5 3 189 192 186
1 5 3 189 192 186
2 5 3 189 192 186
3 5 3 125 83 44
-16 6 3 189 192 186
-15 6 3 189 192 186
-14 6 3 189 192 186
-13 6 3 189 192 186
-12 6 3 189 192 186
-11 6 3 189 192 186
-10 6 3 189 192 186
-9 6 3 189 192 186
-8 6 3 189 192 186
-7 6 3 189 192 186
-6 6 3 189 192 186
-5 6 3 189 192 186
-4 6 3 189 192 186
-3 6 3 189 192 186
-2 6 3 189 192 186
-1 6 3 189 192 186
0 6 3 189 192 186
1 6 3 189 192 186
2 6 3 189 192 186
-16 7 3 189 192 186
-15 7 3 189 192 186
-14 7 3 189 192 186
-13 7 3 189 192 186
-12 7 3 189 192 186
-11 7 3 189 192 186
-10 7 3 189 192 186
-9 7 3 189 192 186
-8 7 3 189 192 186
-7 7 3 189 192 186
-6 7 3 189 192 186
-5 7 3 189 192 186
-4 7 3 189 192 186
-3 7 3 189 192 186
-2 7 3 189 192 186
-1 7 3 189 192 186
0 7 3 189 192 186
1 7 3 189 192 186
2 7 3 189 192 186
3 7 3 105 176 172
4 7 3 105 176 172
5 7 3 105 176 172
6 7 3 105 176 172
-16 8 3 189 192 186
-15 8 3 189 192 186
-14 8 3 189 192 186
-13 8 3 189 192 186
-12 8 3 189 192 186
-11 8 3 189 192 186
-10 8 3 189 192 186
-9 8 3 189 192 186
-8 8 3 189 192 186
-7 8 3 189 192 186
-6 8 3 189 192 186
-5 8 3 189 192 186
-4 8 3 189 192 186
-3 8 3 189 192 186
-2 8 3 189 192 186
-1 8 3 189 192 186
0 8 3 189 192 186
1 8 3 189 192 186
2 8 3 189 192 186
3 8 3 105 176 172
4 8 3 105 176 172
5 8 3 105 176 172
6 8 3 105 176 172
-16 9 3 189 192 186
-15 9 3 189 192 186
-14 9 3 189 192 186
-13 9 3 189 192 186
-12 9 3 189 192 186
-11 9 3 189 192 186
-10 9 3 189 192 186
-9 9 3 189 192 186
-8 9 3 189 192 186
-7 9 3 189 192 186
-6 9 3 189 192 186
-5 9 3 189 192 186
-4 9 3 189 192 186
-3 9 3 189 192 186
-2 9 3 189 192 186
-1 9 3 189 192 186
0 9 3 189 192 186
1 9 3 189 192 186
2 9 3 189 192 186
3 9 3 105 176 172
4 9 3 105 176 172
5 9 3 105 176 172
6 9 3 105 176 172
-16 10 3 189 192 186
-15 10 3 189 192 186
-14 10 3 189 192 186
-13 10 3 189 192 186
-12 10 3 189 192 186
-11 10 3 189 192 186
-10 10 3 189 192 186
-9 10 3 189 192 186
-8 10 3 189 192 186
-7 10 3 189 192 186
-6 10 3 189 192 186
-5 10 3 189 192 186
-4 10 3 189 192 186
-3 10 3 189 192 186
-2 10 3 189 192 186
-1 10 3 189 192 186
0 10 3 189 192 186
1 10 3 189 192 186
2 10 3 189 192 186
3 10 3 105 176 172
4 10 3 105 176 172
5 10 3 105 176 172
6 10 3 105 176 172
-16 11 3 189 192 186
-15 11 3 189 192 186
-14 11 3 189 192 186
-13 11 3 189 192 186
-12 11 3 189 192 186
-11 11 3 189 192 186
-10 11 3 189 192 186
-9 11 3 189 192 186
-8 11 3 189 192 186
-7 11 3 189 192 186
-6 11 3 189 192 186
-5 11 3 189 192 186
-4 11 3 189 192 186
-3 11 3 189 192 186
-2 11 3 189 192 186
-1 11 3 189 192 186
0 11 3 189 192 186
1 11 3 189 192 186
2 11 3 189 192 186
3 11 3 105 176 172
4 11 3 105 176 172
5 11 3 105 176 172
6 11 3 105 176 172
-16 12 3 189 192 186
-15 12 3 189 192 186
-14 12 3 189 192 186
-13 12 3 189 192 186
-12 12 3 189 192 186
-11 12 3 189 192 186
-10 12 3 189 192 186
-9 12 3 189 192 186
-8 12 3 189 192 186
-7 12 3 189 192 186
-6 12 3 189 192 186
-5 12 3 189 192 186
-4 12 3 189 192 186
-3 12 3 189 192 186
-2 12 3 189 192 186
-1 12 3 189 192 186
0 12 3 189 192 186
1 12 3 189 192 186
2 12 3 189 192 186
3 12 3 105 176 172
4 12 3 105 176 172
5 12 3 105 176 172
6 12 3 105 176 172
-16 13 3 189 192 186
-15 13 3 189 192 186
-14 13 3 189 192 186
-13 13 3 189 192 186
-12 13 3 189 192 186
-11 13 3 189 192 186
-10 13 3 189 192 186
-9 13 3 189 192 186
-8 13 3 189 192 186
-7 13 3 189 192 186
-6 13 3 189 192 186
-5 13 3 189 192 186
-4 13 3 189 192 186
-3 13 3 189 192 186
-2 13 3 189 192 186
-1 13 3 189 192 186
0 13 3 189 192 186
1 13 3 189 192 186
2 13 3 189 192 186
3 13 3 105 176 172
4 13 3 105 176 172
5 13 3 105 176 172
6 13 3 105 176 172
-16 14 3 189 192 186
-15 14 3 189 192 186
-14 14 3 189 192 186
-13 14 3 189 192 186
-12 14 3 189 192 186
-11 14 3 189 192 186
-10 14 3 189 192 186
-9 14 3 189 192 186
-8 14 3 189 192 186
-7 14 3 189 192 186
-6 14 3 189 192 186
-5 14 3 189 192 186
-4 14 3 189 192 186
-3 14 3 189 192 186
-2 14 3 189 192 186
-1 14 3 189 192 186
0 14 3 189 192 186
1 14 3 189 192 186
2 14 3 189 192 186
-16 15 3 189 192 186
-15 15 3 189 192 186
-14 15 3 189 192 186
-13 15 3 189 192 186
-12 15 3 189 192 186
-11 15 3 189 192 186
-10 15 3 189 192 186
-9 15 3 189 192 186
-8 15 3 189 192 186
-7 15 3 189 192 186
-6 15 3 189 192 186
-5 15 3 189 192 186
-4 15 3 189 192 186
-3 15 3 189 192 186
-2 15 3 189 192 186
-1 15 3 189 192 186
0 15 3 189 192 186
1 15 3 189 192 186
2 15 3 189 192 186
-16 16 3 189 192 186
-15 16 3 189 192 186
-14 16 3 189 192 186
-13 16 3 189 192 186
-12 16 3 189 192 186
-11 16 3 189 192 186
-10 16 3 189 192 186
-9 16 3 189 192 186
-8 16 3 189 192 186
-7 16 3 189 192 186
-6 16 3 189 192 186
-5 16 3 189 192 186
-4 16 3 189 192 186
-3 16 3 189 192 186
-2 16 3 189 192 186
-1 16 3 189 192 186
0 16 3 189 192 186
1 16 3 189 192 186
2 16 3 189 192 186
-16 17 3 189 192 186
-15 17 3 189 192 186
-14 17 3 189 192 186
-13 17 3 189 192 186
-12 17 3 189 192 186
-11 17 3 189 192 186
-10 17 3 189 192 186
-9 17 3 189 192 186
-8 17 3 189 192 186
-7 17 3 189 192 186
-6 17 3 189 192 186
-5 17 3 189 192 186
-4 17 3 189 192 186
-3 17 3 189 192 186
-2 17 3 189 192 186
-1 17 3 189 192 186
0 17 3 189 192 186
1 17 3 189 192 186
2 17 3 189 192 186
-16 18 3 189 192 186
-15 18 3 189 192 186
-14 18 3 189 192 186
-13 18 3 189 192 186
-12 18 3 189 192 186
-11 18 3 189 192 186
-10 18 3 189 192 186
-9 18 3 189 192 186
-8 18 3 189 192 186
-7 18 3 189 192 186
-6 18 3 189 192 186
-5 18 3 189 192 186
-4 18 3 189 192 186
-3 18 3 189 192 186
-2 18 3 189 192 186
-1 18 3 189 192 186
0 18 3 189 192 186
1 18 3 189 192 186
2 18 3 189 192 186
-16 19 3 189 192 186
-15 19 3 189 192 186
-14 19 3 189 192 186
-13 19 3 189 192 186
-12 19 3 189 192 186
-11 19 3 189 192 186
-10 19 3 189 192 186
-9 19 3 189 192 186
-8 19 3 189 192 186
-7 19 3 189 192 186
-6 19 3 189 192 186
-5 19 3 189 192 186
-4 19 3 189 192 186
-3 19 3 189 192 186
-2 19 3 189 192 186
-1 19 3 189 192 186
0 19 3 189 192 186
1 19 3 189 192 186
2 19 3 189 192 186
-14 -6 4 110 85 47
-12 -6 4 110 85 47
-10 -6 4 110 85 47
-8 -6 4 110 85 47
-6 -6 4 110 85 47
-4 -6 4 110 85 47
-2 -6 4 110 85 47
0 -6 4 125 83 44
2 -6 4 125 83 44
-14 -5 4 125 83 44
-13 -5 4 125 83 44
-12 -5 4 125 83 44
-11 -5 4 125 83 44
-10 -5 4 125 83 44
-9 -5 4 125 83 44
-8 -5 4 125 83 44
-7 -5 4 125 83 44
-6 -5 4 125 83 44
-5 -5 4 125 83 44
-4 -5 4 125 83 44
-3 -5 4 125 83 44
-2 -5 4 125 83 44
-1 -5 4 125 83 44
0 -5 4 125 83 44
1 -5 4 125 83 44
2 -5 4 125 83 44
3 -5 4 125 83 44
-16 -4 4 189 192 186
-15 -4 4 189 192 186
-14 -4 4 255 255 251
-13 -4 4 255 255 251
-12 -4 4 255 255 251
-11 -4 4 255 255 251
-10 -4 4 255 255 251
-9 -4 4 255 255 251
-8 -4 4 255 255 251
-7 -4 4 255 255 251
-6 -4 4 255 255 251
-5 -4 4 255 255 251
-4 -4 4 255 255 251
-3 -4 4 255 255 251
-2 -4 4 255 255 251
-1 -4 4 189 192 186
0 -4 4 189 192 186
1 -4 4 189 192 186
2 -4 4 189 192 186
3 -4 4 125 83 44
4 -4 4 125 83 44
-16 -3 4 189 192 186
-15 -3 4 189 192 186
-14 -3 4 255 255 251
-13 -3 4 187 187 187
-12 -3 4 187 187 187
-11 -3 4 187 187 187
-10 -3 4 187 187 187
-9 -3 4 255 255 251
-8 -3 4 255 255 251
-7 -3 4 187 187 187
-6 -3 4 187 187 187
-5 -3 4 187 187 187
-4 -3 4 187 187 187
-3 -3 4 255 255 251
-2 -3 4 255 255 251
-1 -3 4 189 192 186
0 -3 4 189 192 186
1 -3 4 189 192 186
2 -3 4 189 192 186
3 -3 4 125 83 44
-16 -2 4 189 192 186
-15 -2 4 189 192 186
-14 -2 4 255 255 251
-13 -2 4 187 187 187
-12 -2 4 187 187 187
-11 -2 4 187 187 187
-10 -2 4 187 187 187
-9 -2 4 255 255 251
-8 -2 4 255 255 251
-7 -2 4 187 187 187
-6 -2 4 187 187 187
-5 -2 4 187 187 187
-4 -2 4 187 187 187
-3 -2 4 255 255 251
-2 -2 4 255 255 251
-1 -2 4 189 192 186
0 -2 4 189 192 186
1 -2 4 189 192 186
2 -2 4 189 192 186
3 -2 4 125 83 44
4 -2 4 125 83 44
-16 -1 4 189 192 186
-15 -1 4 189 192 186
-14 -1 4 255 255 251
-13 -1 4 187 187 187
-12 -1 4 187 187 187
-11 -1 4 187 187 187
-10 -1 4 187 187 187
-9 -1 4 255 255 251
-8 -1 4 255 255 251
-7 -1 4 255 255 251
-6 -1 4 255 255 251
-5 -1 4 255 255 251
-4 -1 4 255 255 251
-3 -1 4 255 255 251
-2 -1 4 255 255 251
-1 -1 4 189 192 186
0 -1 4 189 192 186
1 -1 4 189 192 186
2 -1 4 189 192 186
3 -1 4 125 83 44
-16 0 4 189 192 186
-15 0 4 189 192 186
-14 0 4 255 255 251
-13 0 4 255 255 251
-12 0 4 255 255 251
-11 0 4 255 255 251
-10 0 4 255 255 251
-9 0 4 255 255 251
-8 0 4 255 255 251
-7 0 4 255 255 251
-6 0 4 255 255 251
-5 0 4 255 255 251
-4 0 4 255 255 251
-3 0 4 255 255 251
-2 0 4 255 255 251
-1 0 4 189 192 186
0 0 4 189 192 186
1 0 4 189 192 186
2 0 4 189 192 186
3 0 4 125 83 44
4 0 4 125 83 44
-16 1 4 189 192 186
-15 1 4 189 192 186
-14 1 4 189 192 186
-13 1 4 189 192 186
-12 1 4 189 192 186
-11 1 4 189 192 186
-10 1 4 189 192 186
-9 1 4 189 192 186
-8 1 4 189 192 186
-7 1 4 189 192 186
-6 1 4 189 192 186
-5 1 4 189 192 186
-4 1 4 189 192 186
-3 1 4 189 192 186
-2 1 4 189 192 186
-1 1 4 189 192 186
0 1 4 189 192 186
1 1 4 189 192 186
2 1 4 189 192 186
3 1 4 125 83 44
-16 2 4 189 192 186
-15 2 4 189 192 186
-14 2 4 189 192 186
-13 2 4 189 192 186
-12 2 4 189 192 186
-11 2 4 189 192 186
-10 2 4 189 192 186
-9 2 4 189 192 186
-8 2 4 189 192 186
-7 2 4 189 192 186
-6 2 4 189 192 186
-5 2 4 189 192 186
-4 2 4 189 192 186
-3 2 4 189 192 186
-2 2 4 189 192 186
-1 2 4 189 192 186
0 2 4 189 192 186
1 2 4 189 192 186
2 2 4 189 192 186
3 2 4 125 83 44
4 2 4 125 83 44
-16 3 4 189 192 186
-15 3 4 189 192 186
-14 3 4 189 192 186
-13 3 4 189 192 186
-12 3 4 189 192 186
-11 3 4 189 192 186
-10 3 4 189 192 186
-9 3 4 189 192 186
-8 3 4 189 192 186
-7 3 4 189 192 186
-6 3 4 189 192 186
-5 3 4 189 192 186
-4 3 4 189 192 186
-3 3 4 189 192 186
-2 3 4 189 192 186
-1 3 4 189 192 186
0 3 4 189 192 186
1 3 4 189 192 186
2 3 4 189 192 186
3 3 4 125 83 44
-16 4 4 189 192 186
-15 4 4 189 192 186
-14 4 4 189 192 186
-13 4 4 189 192 186
-12 4 4 189 192 186
-11 4 4 189 192 186
-10 4 4 189 192 186
-9 4 4 189 192 186
-8 4 4 189 192 186
-7 4 4 189 192 186
-6 4 4 189 192 186
-5 4 4 189 192 186
-4 4 4 189 192 186
-3 4 4 189 192 186
-2 4 4 189 192 186
-1 4 4 189 192 186
0 4 4 189 192 186
1 4 4 189 192 186
2 4 4 189 192 186
3 4 4 125 83 44
4 4 4 125 83 44
-16 5 4 189 192 186
-15 5 4 189 192 186
-14 5 4 189 192 186
-13 5 4 189 192 186
-12 5 4 189 192 186
-11 5 4 189 192 186
-10 5 4 189 192 186
-9 5 4 189 192 186
-8 5 4 189 192 186
-7 5 4 189 192 186
-6 5 4 189 192 186
-5 5 4 189 192 186
-4 5 4 189 192 186
-3 5 4 189 192 186
-2 5 4 189 192 186
-1 5 4 189 192 186
0 5 4 189 192 186
1 5 4 189 192 186
2 5 4 189 192 186
3 5 4 125 83 44
-16 6 4 189 192 186
-15 6 4 189 192 186
-14 6 4 189 192 186
-13 6 4 189 192 186
-12 6 4 189 192 186
-11 6 4 189 192 186
-10 6 4 189 192 186
-9 6 4 189 192 186
-8 6 4 189 192 186
-7 6 4 189 192 186
-6 6 4 189 192 186
-5 6 4 189 192 186
-4 6 4 189 192 186
-3 6 4 189 192 186
-2 6 4 189 192 186
-1 6 4 189 192 186
0 6 4 189 192 186
1 6 4 189 192 186
2 6 4 189 192 186
-16 7 4 189 192 186
-15 7 4 189 192 186
-14 7 4 189 192 186
-13 7 4 189 192 186
-12 7 4 189 192 186
-11 7 4 189 192 186
-10 7 4 189 192 186
-9 7 4 189 192 186
-8 7 4 189 192 186
-7 7 4 189 192 186
-6 7 4 189 192 186
-5 7 4 189 192 186
-4 7 4 189 192 186
-3 7 4 189 192 186
-2 7 4 189 192 186
-1 7 4 189 192 186
0 7 4 189 192 186
1 7 4 189 192 186
2 7 4 189 192 186
3 7 4 105 176 172
4 7 4 105 176 172
5 7 4 105 176 172
6 7 4 105 176 172
-16 8 4 189 192 186
-15 8 4 189 192 186
-14 8 4 189 192 186
-13 8 4 189 192 186
-12 8 4 189 192 186
-11 8 4 189 192 186
-10 8 4 189 192 186
-9 8 4 189 192 186
-8 8 4 189 192 186
-7 8 4 189 192 186
-6 8 4 189 192 186
-5 8 4 189 192 186
-4 8 4 189 192 186
-3 8 4 189 192 186
-2 8 4 189 192 186
-1 8 4 189 192 186
0 8 4 189 192 186
1 8 4 189 192 186
2 8 4 189 192 186
3 8 4 105 176 172
4 8 4 255 255 251
-16 9 4 189 192 186
-15 9 4 189 192 186
-14 9 4 189 192 186
-13 9 4 189 192 186
-12 9 4 189 192 186
-11 9 4 189 192 186
-10 9 4 189 192 186
-9 9 4 189 192 186
-8 9 4 189 192 186
-7 9 4 189 192 186
-6 9 4 189 192 186
-5 9 4 189 192 186
-4 9 4 189 192 186
-3 9 4 189 192 186
-2 9 4 189 192 186
-1 9 4 189 192 186
0 9 4 189 192 186
1 9 4 189 192 186
2 9 4 189 192 186
3 9 4 105 176 172
4 9 4 255 255 251
5 9 4 177 180 121
-16 10 4 189 192 186
-15 10 4 189 192 186
-14 10 4 189 192 186
-13 10 4 189 192 186
-12 10 4 189 192 186
-11 10 4 189 192 186
-10 10 4 189 192 186
-9 10 4 189 192 186
-8 10 4 189 192 186
-7 10 4 189 192 186
-6 10 4 189 192 186
-5 10 4 189 192 186
-4 10 4 189 192 186
-3 10 4 189 192 186
-2 10 4 189 192 186
-1 10 4 189 192 186
0 10 4 189 192 186
1 10 4 189 192 186
2 10 4 189 192 186
3 10 4 105 176 172
4 10 4 255 255 251
-16 11 4 189 192 186
-15 11 4 189 192 186
-14 11 4 189 192 186
-13 11 4 189 192 186
-12 11 4 189 192 186
-11 11 4 189 192 186
-10 11 4 189 192 186
-9 11 4 189 192 186
-8 11 4 189 192 186
-7 11 4 189 192 186
-6 11 4 189 192 186
-5 11 4 189 192 186
-4 11 4 189 192 186
-3 11 4 189 192 186
-2 11 4 189 192 186
-1 11 4 189 192 186
0 11 4 189 192 186
1 11 4 189 192 186
2 11 4 189 192 186
3 11 4 105 176 172
4 11 4 255 255 251
5 11 4 165 160 81
-16 12 4 189 192 186
-15 12 4 189 192 186
-14 12 4 189 192 186
-13 12 4 189 192 186
-12 12 4 189 192 186
-11 12 4 189 192 186
-10 12 4 189 192 186
-9 12 4 189 192 186
-8 12 4 189 192 186
-7 12 4 189 192 186
-6 12 4 189 192 186
-5 12 4 189 192 186
-4 12 4 189 192 186
-3 12 4 189 192 186
-2 12 4 189 192 186
-1 12 4 189 192 186
0 12 4 189 192 186
1 12 4 189 192 186
2 12 4 189 192 186
3 12 4 105 176 172
4 12 4 255 255 251
-16 13 4 189 192 186
-15 13 4 189 192 186
-14 13 4 189 192 186
-13 13 4 189 192 186
-12 13 4 189 192 186
-11 13 4 189 192 186
-10 13 4 189 192 186
-9 13 4 189 192 186
-8 13 4 189 192 186
-7 13 4 189 192 186
-6 13 4 189 192 186
-5 13 4 189 192 186
-4 13 4 189 192 186
-3 13 4 189 192 186
-2 13 4 189 192 186
-1 13 4 189 192 186
0 13 4 189 192 186
1 13 4 189 192 186
2 13 4 189 192 186
3 13 4 105 176 172
4 13 4 105 176 172
5 13 4 105 176 172
6 13 4 105 176 172
-16 14 4 189 192 186
-15 14 4 189 192 186
-14 14 4 189 192 186
-13 14 4 189 192 186
-12 14 4 189 192 186
-11 14 4 189 192 186
-10 14 4 189 192 186
-9 14 4 189 192 186
-8 14 4 189 192 186
-7 14 4 189 192 186
-6 14 4 189 192 186
-5 14 4 189 192 186
-4 14 4 189 192 186
-3 14 4 189 192 186
-2 14 4 189 192 186
-1 14 4 189 192 186
0 14 4 189 192 186
1 14 4 189 192 186
2 14 4 189 192 186
-16 15 4 189 192 186
-15 15 4 189 192 186
-14 15 4 189 192 186
-13 15 4 189 192 186
-12 15 4 189 192 186
-11 15 4 189 192 186
-10 15 4 189 192 186
-9 15 4 189 192 186
-8 15 4 189 192 186
-7 15 4 189 192 186
-6 15 4 189 192 186
-5 15 4 189 192 186
-4 15 4 189 192 186
-3 15 4 189 192 186
-2 15 4 189 192 186
-1 15 4 189 192 186
0 15 4 189 192 186
1 15 4 189 192 186
2 15 4 189 192 186
-16 16 4 189 192 186
-15 16 4 189 192 186
-14 16 4 189 192 186
-13 16 4 189 192 186
-12 16 4 189 192 186
-11 16 4 189 192 186
-10 16 4 189 192 186
-9 16 4 189 192 186
-8 16 4 189 192 186
-7 16 4 189 192 186
-6 16 4 189 192 186
-5 16 4 189 192 186
-4 16 4 189 192 186
-3 16 4 189 192 186
-2 16 4 189 192 186
-1 16 4 189 192 186
0 16 4 189 192 186
1 16 4 189 192 186
2 16 4 189 192 186
-16 17 4 189 192 186
-15 17 4 189 192 186
-14 17 4 189 192 186
-13 17 4 189 192 186
-12 17 4 189 192 186
-11 17 4 189 192 186
-10 17 4 189 192 186
-9 17 4 189 192 186
-8 17 4 189 192 186
-7 17 4 189 192 186
-6 17 4 189 192 186
-5 17 4 189 192 186
-4 17 4 189 192 186
-3 17 4 189 192 186
-2 17 4 189 192 186
-1 17 4 189 192 186
0 17 4 189 192 186
1 17 4 189 192 186
2 17 4 189 192 186
-16 18 4 189 192 186
-15 18 4 189 192 186
-14 18 4 189 192 186
-13 18 4 189 192 186
-12 18 4 189 192 186
-11 18 4 189 192 186
-10 18 4 189 192 186
-9 18 4 189 192 186
-8 18 4 189 192 186
-7 18 4 189 192 186
-6 18 4 189 192 186
-5 18 4 189 192 186
-4 18 4 189 192 186
-3 18 4 189 192 186
-2 18 4 189 192 186
-1 18 4 189 192 186
0 18 4 189 192 186
1 18 4 189 192 186
2 18 4 189 192 186
-16 19 4 189 192 186
-15 19 4 189 192 186
-14 19 4 189 192 186
-13 19 4 189 192 186
-12 19 4 189 192 186
-11 19 4 189 192 186
-10 19 4 189 192 186
-9 19 4 189 192 186
-8 19 4 189 192 186
-7 19 4 189 192 186
-6 19 4 189 192 186
-5 19 4 189 192 186
-4 19 4 189 192 186
-3 19 4 189 192 186
-2 19 4 189 192 186
-1 19 4 189 192 186
0 19 4 189 192 186
1 19 4 189 192 186
2 19 4 189 192 186
-16 -4 5 189 192 186
-15 -4 5 189 192 186
-16 -3 5 189 192 186
-15 -3 5 189 192 186
-16 -2 5 189 192 186
-15 -2 5 189 192 186
-16 -1 5 189 192 186
-15 -1 5 189 192 186
-16 0 5 189 192 186
-15 0 5 189 192 186
-16 1 5 189 192 186
-15 1 5 189 192 186
-14 1 5 189 192 186
-13 1 5 189 192 186
-12 1 5 189 192 186
-11 1 5 189 192 186
-10 1 5 189 192 186
-9 1 5 189 192 186
-8 1 5 189 192 186
-7 1 5 189 192 186
-6 1 5 189 192 186
-5 1 5 189 192 186
-4 1 5 189 192 186
-3 1 5 189 192 186
-2 1 5 189 192 186
-16 2 5 189 192 186
-15 2 5 189 192 186
-14 2 5 189 192 186
-13 2 5 189 192 186
-12 2 5 189 192 186
-11 2 5 189 192 186
-10 2 5 189 192 186
-9 2 5 189 192 186
-8 2 5 189 192 186
-7 2 5 189 192 186
-6 2 5 189 192 186
-5 2 5 189 192 186
-4 2 5 189 192 186
-3 2 5 189 192 186
-2 2 5 189 192 186
-16 3 5 189 192 186
-15 3 5 189 192 186
-14 3 5 189 192 186
-13 3 5 189 192 186
-12 3 5 189 192 186
-11 3 5 189 192 186
-10 3 5 189 192 186
-9 3 5 189 192 186
-8 3 5 189 192 186
-7 3 5 189 192 186
-6 3 5 189 192 186
-5 3 5 189 192 186
-4 3 5 189 192 186
-3 3 5 189 192 186
-2 3 5 189 192 186
-16 4 5 189 192 186
-15 4 5 189 192 186
-14 4 5 189 192 186
-13 4 5 189 192 186
-12 4 5 189 192 186
-11 4 5 189 192 186
-10 4 5 189 192 186
-9 4 5 189 192 186
-8 4 5 189 192 186
-7 4 5 189 192 186
-6 4 5 189 192 186
-5 4 5 189 192 186
-4 4 5 189 192 186
-3 4 5 189 192 186
-2 4 5 189 192 186
-16 5 5 189 192 186
-15 5 5 189 192 186
-14 5 5 189 192 186
-13 5 5 189 192 186
-12 5 5 189 192 186
-11 5 5 189 192 186
-10 5 5 189 192 186
-9 5 5 189 192 186
-8 5 5 189 192 186
-7 5 5 189 192 186
-6 5 5 189 192 186
-5 5 5 189 192 186
-4 5 5 189 192 186
-3 5 5 189 192 186
-2 5 5 189 192 186
-16 6 5 189 192 186
-15 6 5 189 192 186
-14 6 5 189 192 186
-13 6 5 189 192 186
-12 6 5 189 192 186
-11 6 5 189 192 186
-10 6 5 189 192 186
-9 6 5 189 192 186
-8 6 5 189 192 186
-7 6 5 189 192 186
-6 6 5 189 192 186
-5 6 5 189 192 186
-4 6 5 189 192 186
-3 6 5 189 192 186
-2 6 5 189 192 186
-1 6 5 189 192 186
0 6 5 189 192 186
1 6 5 189 192 186
2 6 5 189 192 186
-16 7 5 189 192 186
-15 7 5 189 192 186
-14 7 5 189 192 186
-13 7 5 189 192 186
-12 7 5 189 192 186
-11 7 5 189 192 186
-10 7 5 189 192 186
-9 7 5 189 192 186
-8 7 5 189 192 186
-7 7 5 189 192 186
-6 7 5 189 192 186
-5 7 5 189 192 186
-4 7 5 189 192 186
-3 7 5 189 192 186
-2 7 5 189 192 186
-1 7 5 189 192 186
0 7 5 189 192 186
1 7 5 189 192 186
2 7 5 189 192 186
3 7 5 105 176 172
4 7 5 105 176 172
5 7 5 105 176 172
6 7 5 105 176 172
-16 8 5 189 192 186
-15 8 5 189 192 186
-14 8 5 189 192 186
-13 8 5 189 192 186
-12 8 5 189 192 186
-11 8 5 189 192 186
-10 8 5 189 192 186
-9 8 5 189 192 186
-8 8 5 189 192 186
-7 8 5 189 192 186
-6 8 5 189 192 186
-5 8 5 189 192 186
-4 8 5 189 192 186
-3 8 5 189 192 186
-2 8 5 189 192 186
-1 8 5 189 192 186
0 8 5 189 192 186
1 8 5 189 192 186
2 8 5 189 192 186
3 8 5 105 176 172
4 8 5 255 255 251
-16 9 5 189 192 186
-15 9 5 189 192 186
-14 9 5 189 192 186
-13 9 5 189 192 186
-12 9 5 189 192 186
-11 9 5 189 192 186
-10 9 5 189 192 186
-9 9 5 189 192 186
-8 9 5 189 192 186
-7 9 5 189 192 186
-6 9 5 189 192 186
-5 9 5 189 192 186
-4 9 5 189 192 186
-3 9 5 189 192 186
-2 9 5 189 192 186
-1 9 5 189 192 186
0 9 5 189 192 186
1 9 5 189 192 186
2 9 5 189 192 186
3 9 5 105 176 172
4 9 5 255 255 251
-16 10 5 189 192 186
-15 10 5 189 192 186
-14 10 5 189 192 186
-13 10 5 189 192 186
-12 10 5 189 192 186
-11 10 5 189 192 186
-10 10 5 189 192 186
-9 10 5 189 192 186
-8 10 5 189 192 186
-7 10 5 189 192 186
-6 10 5 189 192 186
-5 10 5 189 192 186
-4 10 5 189 192 186
-3 10 5 189 192 186
-2 10 5 189 192 186
-1 10 5 189 192 186
0 10 5 189 192 186
1 10 5 189 192 186
2 10 5 189 192 186
3 10 5 105 176 172
4 10 5 255 255 251
-16 11 5 189 192 186
-15 11 5 189 192 186
-14 11 5 189 192 186
-13 11 5 189 192 186
-12 11 5 189 192 186
-11 11 5 189 192 186
-10 11 5 189 192 186
-9 11 5 189 192 186
-8 11 5 189 192 186
-7 11 5 189 192 186
-6 11 5 189 192 186
-5 11 5 189 192 186
-4 11 5 189 192 186
-3 11 5 189 192 186
-2 11 5 189 192 186
-1 11 5 189 192 186
0 11 5 189 192 186
1 11 5 189 192 186
2 11 5 189 192 186
3 11 5 105 176 172
4 11 5 255 255 251
-16 12 5 189 192 186
-15 12 5 189 192 186
-14 12 5 189 192 186
-13 12 5 189 192 186
-12 12 5 189 192 186
-11 12 5 189 192 186
-10 12 5 189 192 186
-9 12 5 189 192 186
-8 12 5 189 192 186
-7 12 5 189 192 186
-6 12 5 189 192 186
-5 12 5 189 192 186
-4 12 5 189 192 186
-3 12 5 189 192 186
-2 12 5 189 192 186
-1 12 5 189 192 186
0 12 5 189 192 186
1 12 5 189 192 186
2 12 5 189 192 186
3 12 5 105 176 172
4 12 5 255 255 251
-16 13 5 189 192 186
-15 13 5 189 192 186
-14 13 5 189 192 186
-13 13 5 189 192 186
-12 13 5 189 192 186
-11 13 5 189 192 186
-10 13 5 189 192 186
-9 13 5 189 192 186
-8 13 5 189 192 186
-7 13 5 189 192 186
-6 13 5 189 192 186
-5 13 5 189 192 186
-4 13 5 189 192 186
-3 13 5 189 192 186
-2 13 5 189 192 186
-1 13 5 189 192 186
0 13 5 189 192 186
1 13 5 189 192 186
2 13 5 189 192 186
3 13 5 105 176 172
4 13 5 105 176 172
5 13 5 105 176 172
6 13 5 105 176 172
-16 14 5 189 192 186
-15 14 5 189 192 186
-14 14 5 189 192 186
-13 14 5 189 192 186
-12 14 5 189 192 186
-11 14 5 189 192 186
-10 14 5 189 192 186
-9 14 5 189 192 186
-8 14 5 189 192 186
-7 14 5 189 192 186
-6 14 5 189 192 186
-5 14 5 189 192 186
-4 14 5 189 192 186
-3 14 5 189 192 186
-2 14 5 189 192 186
-1 14 5 189 192 186
0 14 5 189 192 186
1 14 5 189 192 186
2 14 5 189 192 186
-16 15 5 189 192 186
-15 15 5 189 192 186
-14 15 5 189 192 186
-13 15 5 189 192 186
-12 15 5 189 192 186
-11 15 5 189 192 186
-10 15 5 189 192 186
-9 15 5 189 192 186
-8 15 5 189 192 186
-7 15 5 189 192 186
-6 15 5 189 192 186
-5 15 5 189 192 186
-4 15 5 189 192 186
-3 15 5 189 192 186
-2 15 5 189 192 186
-1 15 5 189 192 186
0 15 5 189 192 186
1 15 5 189 192 186
2 15 5 189 192 186
-16 16 5 189 192 186
-15 16 5 189 192 186
-14 16 5 189 192 186
-13 16 5 189 192 186
-12 16 5 189 192 186
-11 16 5 189 192 186
-10 16 5 189 192 186
-9 16 5 189 192 186
-8 16 5 189 192 186
-7 16 5 189 192 186
-6 16 5 189 192 186
-5 16 5 189 192 186
-4 16 5 189 192 186
-3 16 5 189 192 186
-2 16 5 189 192 186
-1 16 5 189 192 186
0 16 5 189 192 186
1 16 5 189 192 186
2 16 5 189 192 186
-16 17 5 189 192 186
-15 17 5 189 192 186
-14 17 5 189 192 186
-13 17 5 189 192 186
-12 17 5 189 192 186
-11 17 5 189 192 186
-10 17 5 189 192 186
-9 17 5 189 192 186
-8 17 5 189 192 186
-7 17 5 189 192 186
-6 17 5 189 192 186
-5 17 5 189 192 186
-4 17 5 189 192 186
-3 17 5 189 192 186
-2 17 5 189 192 186
-1 17 5 189 192 186
0 17 5 189 192 186
1 17 5 189 192 186
2 17 5 189 192 186
-16 18 5 189 192 186
-15 18 5 189 192 186
-14 18 5 189 192 186
-13 18 5 189 192 186
-12 18 5 189 192 186
-11 18 5 189 192 186
-10 18 5 189 192 186
-9 18 5 189 192 186
-8 18 5 189 192 186
-7 18 5 189 192 186
-6 18 5 189 192 186
-5 18 5 189 192 186
-4 18 5 189 192 186
-3 18 5 189 192 186
-2 18 5 189 192 186
-1 18 5 189 192 186
0 18 5 189 192 186
1 18 5 189 192 186
2 18 5 189 192 186
-16 19 5 189 192 186
-15 19 5 189 192 186
-14 19 5 189 192 186
-13 19 5 189 192 186
-12 19 5 189 192 186
-11 19 5 189 192 186
-10 19 5 189 192 186
-9 19 5 189 192 186
-8 19 5 189 192 186
-7 19 5 189 192 186
-6 19 5 189 192 186
-5 19 5 189 192 186
-4 19 5 189 192 186
-3 19 5 189 192 186
-2 19 5 189 192 186
-1 19 5 189 192 186
0 19 5 189 192 186
1 19 5 189 192 186
2 19 5 189 192 186
-16 -4 6 189 192 186
-15 -4 6 189 192 186
-16 -3 6 189 192 186
-15 -3 6 189 192 186
-16 -2 6 189 192 186
-15 -2 6 189 192 186
-16 -1 6 189 192 186
-15 -1 6 189 192 186
-16 0 6 189 192 186
-15 0 6 189 192 186
-16 1 6 189 192 186
-15 1 6 189 192 186
-14 1 6 189 192 186
-13 1 6 189 192 186
-12 1 6 189 192 186
-11 1 6 189 192 186
-10 1 6 189 192 186
-9 1 6 189 192 186
-8 1 6 189 192 186
-7 1 6 189 192 186
-6 1 6 189 192 186
-5 1 6 189 192 186
-4 1 6 189 192 186
-3 1 6 189 192 186
-2 1 6 189 192 186
-16 2 6 189 192 186
-15 2 6 189 192 186
-14 2 6 189 192 186
-13 2 6 189 192 186
-12 2 6 189 192 186
-11 2 6 189 192 186
-10 2 6 189 192 186
-9 2 6 189 192 186
-8 2 6 189 192 186
-7 2 6 189 192 186
-6 2 6 189 192 186
-5 2 6 189 192 186
-4 2 6 189 192 186
-3 2 6 189 192 186
-2 2 6 189 192 186
-16 3 6 189 192 186
-15 3 6 189 192 186
-14 3 6 189 192 186
-13 3 6 189 192 186
-12 3 6 189 192 186
-11 3 6 189 192 186
-10 3 6 189 192 186
-9 3 6 189 192 186
-8 3 6 189 192 186
-7 3 6 189 192 186
-6 3 6 189 192 186
-5 3 6 189 192 186
-4 3 6 189 192 186
-3 3 6 189 192 186
-2 3 6 189 192 186
-16 4 6 189 192 186
-15 4 6 189 192 186
-14 4 6 189 192 186
-13 4 6 189 192 186
-12 4 6 189 192 186
-11 4 6 189 192 186
-10 4 6 189 192 186
-9 4 6 189 192 186
-8 4 6 189 192 186
-7 4 6 189 192 186
-6 4 6 189 192 186
-5 4 6 189 192 186
-4 4 6 189 192 186
-3 4 6 189 192 186
-2 4 6 189 192 186
-16 5 6 189 192 186
-15 5 6 189 192 186
-14 5 6 189 192 186
-13 5 6 189 192 186
-12 5 6 189 192 186
-11 5 6 189 192 186
-10 5 6 189 192 186
-9 5 6 189 192 186
-8 5 6 189 192 186
-7 5 6 189 192 186
-6 5 6 189 192 186
-5 5 6 189 192 186
-4 5 6 189 192 186
-3 5 6 189 192 186
-2 5 6 189 192 186
-16 6 6 189 192 186
-15 6 6 189 192 186
-14 6 6 189 192 186
-13 6 6 189 192 186
-12 6 6 189 192 186
-11 6 6 189 192 186
-10 6 6 189 192 186
-9 6 6 189 192 186
-8 6 6 189 192 186
-7 6 6 189 192 186
-6 6 6 189 192 186
-5 6 6 189 192 186
-4 6 6 189 192 186
-3 6 6 189 192 186
-2 6 6 189 192 186
-1 6 6 189 192 186
0 6 6 189 192 186
1 6 6 189 192 186
2 6 6 189 192 186
-16 7 6 189 192 186
-15 7 6 189 192 186
-14 7 6 189 192 186
-13 7 6 189 192 186
-12 7 6 189 192 186
-11 7 6 189 192 186
-10 7 6 189 192 186
-9 7 6 189 192 186
-8 7 6 189 192 186
-7 7 6 189 192 186
-6 7 6 189 192 186
-5 7 6 189 192 186
-4 7 6 189 192 186
-3 7 6 189 192 186
-2 7 6 189 192 186
-1 7 6 189 192 186
0 7 6 189 192 186
1 7 6 189 192 186
2 7 6 189 192 186
3 7 6 105 176 172
4 7 6 105 176 172
5 7 6 105 176 172
6 7 6 105 176 172
-16 8 6 189 192 186
-15 8 6 189 192 186
-14 8 6 189 192 186
-13 8 6 189 192 186
-12 8 6 189 192 186
-11 8 6 189 192 186
-10 8 6 189 192 186
-9 8 6 189 192 186
-8 8 6 189 192 186
-7 8 6 189 192 186
-6 8 6 189 192 186
-5 8 6 189 192 186
-4 8 6 189 192 186
-3 8 6 189 192 186
-2 8 6 189 192 186
-1 8 6 189 192 186
0 8 6 189 192 186
1 8 6 189 192 186
2 8 6 189 192 186
3 8 6 105 176 172
4 8 6 105 176 172
5 8 6 145 152 159
-16 9 6 189 192 186
-15 9 6 189 192 186
-14 9 6 189 192 186
-13 9 6 189 192 186
-12 9 6 189 192 186
-11 9 6 189 192 186
-10 9 6 189 192 186
-9 9 6 189 192 186
-8 9 6 189 192 186
-7 9 6 189 192 186
-6 9 6 189 192 186
-5 9 6 189 192 186
-4 9 6 189 192 186
-3 9 6 189 192 186
-2 9 6 189 192 186
-1 9 6 189 192 186
0 9 6 189 192 186
1 9 6 189 192 186
2 9 6 189 192 186
3 9 6 105 176 172
4 9 6 105 176 172
5 9 6 145 152 159
-16 10 6 189 192 186
-15 10 6 189 192 186
-14 10 6 189 192 186
-13 10 6 189 192 186
-12 10 6 189 192 186
-11 10 6 189 192 186
-10 10 6 189 192 186
-9 10 6 189 192 186
-8 10 6 189 192 186
-7 10 6 189 192 186
-6 10 6 189 192 186
-5 10 6 189 192 186
-4 10 6 189 192 186
-3 10 6 189 192 186
-2 10 6 189 192 186
-1 10 6 189 192 186
0 10 6 189 192 186
1 10 6 189 192 186
2 10 6 189 192 186
3 10 6 105 176 172
4 10 6 105 176 172
5 10 6 145 152 159
-16 11 6 189 192 186
-15 11 6 189 192 186
-14 11 6 189 192 186
-13 11 6 189 192 186
-12 11 6 189 192 186
-11 11 6 189 192 186
-10 11 6 189 192 186
-9 11 6 189 192 186
-8 11 6 189 192 186
-7 11 6 189 192 186
-6 11 6 189 192 186
-5 11 6 189 192 186
-4 11 6 189 192 186
-3 11 6 189 192 186
-2 11 6 189 192 186
-1 11 6 189 192 186
0 11 6 189 192 186
1 11 6 189 192 186
2 11 6 189 192 186
3 11 6 105 176 172
4 11 6 105 176 172
5 11 6 145 152 159
-16 12 6 189 192 186
-15 12 6 189 192 186
-14 12 6 189 192 186
-13 12 6 189 192 186
-12 12 6 189 192 186
-11 12 6 189 192 186
-10 12 6 189 192 186
-9 12 6 189 192 186
-8 12 6 189 192 186
-7 12 6 189 192 186
-6 12 6 189 192 186
-5 12 6 189 192 186
-4 12 6 189 192 186
-3 12 6 189 192 186
-2 12 6 189 192 186
-1 12 6 189 192 186
0 12 6 189 192 186
1 12 6 189 192 186
2 12 6 189 192 186
3 12 6 105 176 172
4 12 6 105 176 172
5 12 6 145 152 159
-16 13 6 189 192 186
-15 13 6 189 192 186
-14 13 6 189 192 186
-13 13 6 189 192 186
-12 13 6 189 192 186
-11 13 6 189 192 186
-10 13 6 189 192 186
-9 13 6 189 192 186
-8 13 6 189 192 186
-7 13 6 189 192 186
-6 13 6 189 192 186
-5 13 6 189 192 186
-4 13 6 189 192 186
-3 13 6 189 192 186
-2 13 6 189 192 186
-1 13 6 189 192 186
0 13 6 189 192 186
1 13 6 189 192 186
2 13 6 189 192 186
3 13 6 105 176 172
4 13 6 105 176 172
5 13 6 105 176 172
6 13 6 105 176 172
-16 14 6 189 192 186
-15 14 6 189 192 186
-14 14 6 189 192 186
-13 14 6 189 192 186
-12 14 6 189 192 186
-11 14 6 189 192 186
-10 14 6 189 192 186
-9 14 6 189 192 186
-8 14 6 189 192 186
-7 14 6 189 192 186
-6 14 6 189 192 186
-5 14 6 189 192 186
-4 14 6 189 192 186
-3 14 6 189 192 186
-2 14 6 189 192 186
-1 14 6 189 192 186
0 14 6 189 192 186
1 14 6 189 192 186
2 14 6 189 192 186
-16 15 6 189 192 186
-15 15 6 189 192 186
-14 15 6 189 192 186
-13 15 6 189 192 186
-12 15 6 189 192 186
-11 15 6 189 192 186
-10 15 6 189 192 186
-9 15 6 189 192 186
-8 15 6 189 192 186
-7 15 6 189 192 186
-6 15 6 189 192 186
-5 15 6 189 192 186
-4 15 6 189 192 186
-3 15 6 189 192 186
-2 15 6 189 192 186
-1 15 6 189 192 186
0 15 6 189 192 186
1 15 6 189 192 186
2 15 6 189 192 186
-16 16 6 189 192 186
-15 16 6 189 192 186
-14 16 6 189 192 186
-13 16 6 189 192 186
-12 16 6 189 192 186
-11 16 6 189 192 186
-10 16 6 189 192 186
-9 16 6 189 192 186
-8 16 6 189 192 186
-7 16 6 189 192 186
-6 16 6 189 192 186
-5 16 6 189 192 186
-4 16 6 189 192 186
-3 16 6 189 192 186
-2 16 6 189 192 186
-1 16 6 189 192 186
0 16 6 189 192 186
1 16 6 189 192 186
2 16 6 189 192 186
-16 17 6 189 192 186
-15 17 6 189 192 186
-14 17 6 189 192 186
-13 17 6 189 192 186
-12 17 6 189 192 186
-11 17 6 189 192 186
-10 17 6 189 192 186
-9 17 6 189 192 186
-8 17 6 189 192 186
-7 17 6 189 192 186
-6 17 6 189 192 186
-5 17 6 189 192 186
-4 17 6 189 192 186
-3 17 6 189 192 186
-2 17 6 189 192 186
-1 17 6 189 192 186
0 17 6 189 192 186
1 17 6 189 192 186
2 17 6 189 192 186
-16 18 6 189 192 186
-15 18 6 189 192 186
-14 18 6 189 192 186
-13 18 6 189 192 186
-12 18 6 189 192 186
-11 18 6 189 192 186
-10 18 6 189 192 186
-9 18 6 189 192 186
-8 18 6 189 192 186
-7 18 6 189 192 186
-6 18 6 189 192 186
-5 18 6 189 192 186
-4 18 6 189 192 186
-3 18 6 189 192 186
-2 18 6 189 192 186
-1 18 6 189 192 186
0 18 6 189 192 186
1 18 6 189 192 186
2 18 6 189 192 186
-16 19 6 189 192 186
-15 19 6 189 192 186
-14 19 6 189 192 186
-13 19 6 189 192 186
-12 19 6 189 192 186
-11 19 6 189 192 186
-10 19 6 189 192 186
-9 19 6 189 192 186
-8 19 6 189 192 186
-7 19 6 189 192 186
-6 19 6 189 192 186
-5 19 6 189 192 186
-4 19 6 189 192 186
-3 19 6 189 192 186
-2 19 6 189 192 186
-1 19 6 189 192 186
0 19 6 189 192 186
1 19 6 189 192 186
2 19 6 189 192 186
-16 -4 7 189 192 186
-15 -4 7 189 192 186
-16 -3 7 189 192 186
-15 -3 7 189 192 186
-16 -2 7 189 192 186
-15 -2 7 189 192 186
-16 -1 7 189 192 186
-15 -1 7 189 192 186
-16 0 7 189 192 186
-15 0 7 189 192 186
-16 1 7 189 192 186
-15 1 7 189 192 186
-14 1 7 189 192 186
-13 1 7 189 192 186
-12 1 7 189 192 186
-11 1 7 189 192 186
-10 1 7 189 192 186
-9 1 7 189 192 186
-8 1 7 189 192 186
-7 1 7 189 192 186
-6 1 7 189 192 186
-5 1 7 189 192 186
-4 1 7 189 192 186
-3 1 7 189 192 186
-2 1 7 189 192 186
-16 2 7 189 192 186
-15 2 7 189 192 186
-14 2 7 189 192 186
-13 2 7 189 192 186
-12 2 7 189 192 186
-11 2 7 189 192 186
-10 2 7 189 192 186
-9 2 7 189 192 186
-8 2 7 189 192 186
-7 2 7 189 192 186
-6 2 7 189 192 186
-5 2 7 189 192 186
-4 2 7 189 192 186
-3 2 7 189 192 186
-2 2 7 189 192 186
-16 3 7 189 192 186
-15 3 7 189 192 186
-14 3 7 189 192 186
-13 3 7 189 192 186
-12 3 7 189 192 186
-11 3 7 189 192 186
-10 3 7 189 192 186
-9 3 7 189 192 186
-8 3 7 189 192 186
-7 3 7 189 192 186
-6 3 7 189 192 186
-5 3 7 189 192 186
-4 3 7 189 192 186
-3 3 7 189 192 186
-2 3 7 189 192 186
-16 4 7 189 192 186
-15 4 7 189 192 186
-14 4 7 189 192 186
-13 4 7 189 192 186
-12 4 7 189 192 186
-11 4 7 189 192 186
-10 4 7 189 192 186
-9 4 7 189 192 186
-8 4 7 189 192 186
-7 4 7 189 192 186
-6 4 7 189 192 186
-5 4 7 189 192 186
-4 4 7 189 192 186
-3 4 7 189 192 186
-2 4 7 189 192 186
-16 5 7 189 192 186
-15 5 7 189 192 186
-14 5 7 189 192 186
-13 5 7 189 192 186
-12 5 7 189 192 186
-11 5 7 189 192 186
-10 5 7 189 192 186
-9 5 7 189 192 186
-8 5 7 189 192 186
-7 5 7 189 192 186
-6 5 7 189 192 186
-5 5 7 189 192 186
-4 5 7 189 192 186
-3 5 7 189 192 186
-2 5 7 189 192 186
-16 6 7 189 192 186
-15 6 7 189 192 186
-14 6 7 189 192 186
-13 6 7 189 192 186
-12 6 7 189 192 186
-11 6 7 189 192 186
-10 6 7 189 192 186
-9 6 7 189 192 186
-8 6 7 189 192 186
-7 6 7 189 192 186
-6 6 7 189 192 186
-5 6 7 189 192 186
-4 6 7 189 192 186
-3 6 7 189 192 186
-2 6 7 189 192 186
-1 6 7 189 192 186
0 6 7 189 192 186
1 6 7 189 192 186
2 6 7 189 192 186
-16 7 7 189 192 186
-15 7 7 189 192 186
-14 7 7 189 192 186
-13 7 7 189 192 186
-12 7 7 189 192 186
-11 7 7 189 192 186
-10 7 7 189 192 186
-9 7 7 189 192 186
-8 7 7 189 192 186
-7 7 7 189 192 186
-6 7 7 189 192 186
-5 7 7 189 192 186
-4 7 7 189 192 186
-3 7 7 189 192 186
-2 7 7 189 192 186
-1 7 7 189 192 186
0 7 7 189 192 186
1 7 7 189 192 186
2 7 7 189 192 186
3 7 7 105 176 172
4 7 7 105 176 172
5 7 7 105 176 172
6 7 7 105 176 172
-16 8 7 189 192 186
-15 8 7 189 192 186
-14 8 7 189 192 186
-13 8 7 189 192 186
-12 8 7 189 192 186
-11 8 7 189 192 186
-10 8 7 189 192 186
-9 8 7 189 192 186
-8 8 7 189 192 186
-7 8 7 189 192 186
-6 8 7 189 192 186
-5 8 7 189 192 186
-4 8 7 189 192 186
-3 8 7 189 192 186
-2 8 7 189 192 186
-1 8 7 189 192 186
0 8 7 189 192 186
1 8 7 189 192 186
2 8 7 189 192 186
3 8 7 105 176 172
4 8 7 255 255 251
-16 9 7 189 192 186
-15 9 7 189 192 186
-14 9 7 189 192 186
-13 9 7 189 192 186
-12 9 7 189 192 186
-11 9 7 189 192 186
-10 9 7 189 192 186
-9 9 7 189 192 186
-8 9 7 189 192 186
-7 9 7 189 192 186
-6 9 7 189 192 186
-5 9 7 189 192 186
-4 9 7 189 192 186
-3 9 7 189 192 186
-2 9 7 189 192 186
-1 9 7 189 192 186
0 9 7 189 192 186
1 9 7 189 192 186
2 9 7 189 192 186
3 9 7 105 176 172
4 9 7 255 255 251
5 9 7 180 129 187
-16 10 7 189 192 186
-15 10 7 189 192 186
-14 10 7 189 192 186
-13 10 7 189 192 186
-12 10 7 189 192 186
-11 10 7 189 192 186
-10 10 7 189 192 186
-9 10 7 189 192 186
-8 10 7 189 192 186
-7 10 7 189 192 186
-6 10 7 189 192 186
-5 10 7 189 192 186
-4 10 7 189 192 186
-3 10 7 189 192 186
-2 10 7 189 192 186
-1 10 7 189 192 186
0 10 7 189 192 186
1 10 7 189 192 186
2 10 7 189 192 186
3 10 7 105 176 172
4 10 7 255 255 251
-16 11 7 189 192 186
-15 11 7 189 192 186
-14 11 7 189 192 186
-13 11 7 189 192 186
-12 11 7 189 192 186
-11 11 7 189 192 186
-10 11 7 189 192 186
-9 11 7 189 192 186
-8 11 7 189 192 186
-7 11 7 189 192 186
-6 11 7 189 192 186
-5 11 7 189 192 186
-4 11 7 189 192 186
-3 11 7 189 192 186
-2 11 7 189 192 186
-1 11 7 189 192 186
0 11 7 189 192 186
1 11 7 189 192 186
2 11 7 189 192 186
3 11 7 105 176 172
4 11 7 255 255 251
5 11 7 46 92 110
-16 12 7 189 192 186
-15 12 7 189 192 186
-14 12 7 189 192 186
-13 12 7 189 192 186
-12 12 7 189 192 186
-11 12 7 189 192 186
-10 12 7 189 192 186
-9 12 7 189 192 186
-8 12 7 189 192 186
-7 12 7 189 192 186
-6 12 7 189 192 186
-5 12 7 189 192 186
-4 12 7 189 192 186
-3 12 7 189 192 186
-2 12 7 189 192 186
-1 12 7 189 192 186
0 12 7 189 192 186
1 12 7 189 192 186
2 12 7 189 192 186
3 12 7 105 176 172
4 12 7 255 255 251
-16 13 7 189 192 186
-15 13 7 189 192 186
-14 13 7 189 192 186
-13 13 7 189 192 186
-12 13 7 189 192 186
-11 13 7 189 192 186
-10 13 7 189 192 186
-9 13 7 189 192 186
-8 13 7 189 192 186
-7 13 7 189 192 186
-6 13 7 189 192 186
-5 13 7 189 192 186
-4 13 7 189 192 186
-3 13 7 189 192 186
-2 13 7 189 192 186
-1 13 7 189 192 186
0 13 7 189 192 186
1 13 7 189 192 186
2 13 7 189 192 186
3 13 7 105 176 172
4 13 7 105 176 172
5 13 7 105 176 172
6 13 7 105 176 172
-16 14 7 189 192 186
-15 14 7 189 192 186
-14 14 7 189 192 186
-13 14 7 189 192 186
-12 14 7 189 192 186
-11 14 7 189 192 186
-10 14 7 189 192 186
-9 14 7 189 192 186
-8 14 7 189 192 186
-7 14 7 189 192 186
-6 14 7 189 192 186
-5 14 7 189 192 186
-4 14 7 189 192 186
-3 14 7 189 192 186
-2 14 7 189 192 186
-1 14 7 189 192 186
0 14 7 189 192 186
1 14 7 189 192 186
2 14 7 189 192 186
-16 15 7 189 192 186
-15 15 7 189 192 186
-14 15 7 189 192 186
-13 15 7 189 192 186
-12 15 7 189 192 186
-11 15 7 189 192 186
-10 15 7 189 192 186
-9 15 7 189 192 186
-8 15 7 189 192 186
-7 15 7 189 192 186
-6 15 7 189 192 186
-5 15 7 189 192 186
-4 15 7 189 192 186
-3 15 7 189 192 186
-2 15 7 189 192 186
-1 15 7 189 192 186
0 15 7 189 192 186
1 15 7 189 192 186
2 15 7 189 192 186
-16 16 7 189 192 186
-15 16 7 189 192 186
-14 16 7 189 192 186
-13 16 7 189 192 186
-12 16 7 189 192 186
-11 16 7 189 192 186
-10 16 7 189 192 186
-9 16 7 189 192 186
-8 16 7 189 192 186
-7 16 7 189 192 186
-6 16 7 189 192 186
-5 16 7 189 192 186
-4 16 7 189 192 186
-3 16 7 189 192 186
-2 16 7 189 192 186
-1 16 7 189 192 186
0 16 7 189 192 186
1 16 7 189 192 186
2 16 7 189 192 186
-16 17 7 189 192 186
-15 17 7 189 192 186
-14 17 7 189 192 186
-13 17 7 189 192 186
-12 17 7 189 192 186
-11 17 7 189 192 186
-10 17 7 189 192 186
-9 17 7 189 192 186
-8 17 7 189 192 186
-7 17 7 189 192 186
-6 17 7 189 192 186
-5 17 7 189 192 186
-4 17 7 189 192 186
-3 17 7 189 192 186
-2 17 7 189 192 186
-1 17 7 189 192 186
0 17 7 189 192 186
1 17 7 189 192 186
2 17 7 189 192 186
-16 18 7 189 192 186
-15 18 7 189 192 186
-14 18 7 189 192 186
-13 18 7 189 192 186
-12 18 7 189 192 186
-11 18 7 189 192 186
-10 18 7 189 192 186
-9 18 7 189 192 186
-8 18 7 189 192 186
-7 18 7 189 192 186
-6 18 7 189 192 186
-5 18 7 189 192 186
-4 18 7 189 192 186
-3 18 7 189 192 186
-2 18 7 189 192 186
-1 18 7 189 192 186
0 18 7 189 192 186
1 18 7 189 192 186
2 18 7 189 192 186
-16 19 7 189 192 186
-15 19 7 189 192 186
-14 19 7 189 192 186
-13 19 7 189 192 186
-12 19 7 189 192 186
-11 19 7 189 192 186
-10 19 7 189 192 186
-9 19 7 189 192 186
-8 19 7 189 192 186
-7 19 7 189 192 186
-6 19 7 189 192 186
-5 19 7 189 192 186
-4 19 7 189 192 186
-3 19 7 189 192 186
-2 19 7 189 192 186
-1 19 7 189 192 186
0 19 7 189 192 186
1 19 7 189 192 186
2 19 7 189 192 186
-16 -4 8 189 192 186
-15 -4 8 189 192 186
-16 -3 8 189 192 186
-15 -3 8 189 192 186
-16 -2 8 189 192 186
-15 -2 8 189 192 186
-16 -1 8 189 192 186
-15 -1 8 189 192 186
-16 0 8 189 192 186
-15 0 8 189 192 186
-16 1 8 189 192 186
-15 1 8 189 192 186
-14 1 8 189 192 186
-13 1 8 189 192 186
-12 1 8 189 192 186
-11 1 8 189 192 186
-10 1 8 189 192 186
-9 1 8 189 192 186
-8 1 8 189 192 186
-7 1 8 189 192 186
-6 1 8 189 192 186
-5 1 8 189 192 186
-4 1 8 189 192 186
-3 1 8 189 192 186
-2 1 8 189 192 186
-16 2 8 189 192 186
-15 2 8 189 192 186
-14 2 8 189 192 186
-13 2 8 189 192 186
-12 2 8 189 192 186
-11 2 8 189 192 186
-10 2 8 189 192 186
-9 2 8 189 192 186
-8 2 8 189 192 186
-7 2 8 189 192 186
-6 2 8 189 192 186
-5 2 8 189 192 186
-4 2 8 189 192 186
-3 2 8 189 192 186
-2 2 8 189 192 186
-16 3 8 189 192 186
-15 3 8 189 192 186
-14 3 8 189 192 186
-13 3 8 189 192 186
-12 3 8 189 192 186
-11 3 8 189 192 186
-10 3 8 189 192 186
-9 3 8 189 192 186
-8 3 8 189 192 186
-7 3 8 189 192 186
-6 3 8 189 192 186
-5 3 8 189 192 186
-4 3 8 189 192 186
-3 3 8 189 192 186
-2 3 8 189 192 186
-16 4 8 189 192 186
-15 4 8 189 192 186
-14 4 8 189 192 186
-13 4 8 189 192 186
-12 4 8 189 192 186
-11 4 8 189 192 186
-10 4 8 189 192 186
-9 4 8 189 192 186
-8 4 8 189 192 186
-7 4 8 189 192 186
-6 4 8 189 192 186
-5 4 8 189 192 186
-4 4 8 189 192 186
-3 4 8 189 192 186
-2 4 8 189 192 186
-16 5 8 189 192 186
-15 5 8 189 192 186
-14 5 8 189 192 186
-13 5 8 189 192 186
-12 5 8 189 192 186
-11 5 8 189 192 186
-10 5 8 189 192 186
-9 5 8 189 192 186
-8 5 8 189 192 186
-7 5 8 189 192 186
-6 5 8 189 192 186
-5 5 8 189 192 186
-4 5 8 189 192 186
-3 5 8 189 192 186
-2 5 8 189 192 186
-16 6 8 189 192 186
-15 6 8 189 192 186
-14 6 8 189 192 186
-13 6 8 189 192 186
-12 6 8 189 192 186
-11 6 8 189 192 186
-10 6 8 189 192 186
-9 6 8 189 192 186
-8 6 8 189 192 186
-7 6 8 189 192 186
-6 6 8 189 192 186
-5 6 8 189 192 186
-4 6 8 189 192 186
-3 6 8 189 192 186
-2 6 8 189 192 186
-1 6 8 189 192 186
0 6 8 189 192 186
1 6 8 189 192 186
2 6 8 189 192 186
-16 7 8 189 192 186
-15 7 8 189 192 186
-14 7 8 189 192 186
-13 7 8 189 192 186
-12 7 8 189 192 186
-11 7 8 189 192 186
-10 7 8 189 192 186
-9 7 8 189 192 186
-8 7 8 189 192 186
-7 7 8 189 192 186
-6 7 8 189 192 186
-5 7 8 189 192 186
-4 7 8 189 192 186
-3 7 8 189 192 186
-2 7 8 189 192 186
-1 7 8 189 192 186
0 7 8 189 192 186
1 7 8 189 192 186
2 7 8 189 192 186
3 7 8 105 176 172
4 7 8 105 176 172
5 7 8 105 176 172
6 7 8 105 176 172
-16 8 8 189 192 186
-15 8 8 189 192 186
-14 8 8 189 192 186
-13 8 8 189 192 186
-12 8 8 189 192 186
-11 8 8 189 192 186
-10 8 8 189 192 186
-9 8 8 189 192 186
-8 8 8 189 192 186
-7 8 8 189 192 186
-6 8 8 189 192 186
-5 8 8 189 192 186
-4 8 8 189 192 186
-3 8 8 189 192 186
-2 8 8 189 192 186
-1 8 8 189 192 186
0 8 8 189 192 186
1 8 8 189 192 186
2 8 8 189 192 186
3 8 8 105 176 172
4 8 8 255 255 251
-16 9 8 189 192 186
-15 9 8 189 192 186
-14 9 8 189 192 186
-13 9 8 189 192 186
-12 9 8 189 192 186
-11 9 8 189 192 186
-10 9 8 189 192 186
-9 9 8 189 192 186
-8 9 8 189 192 186
-7 9 8 189 192 186
-6 9 8 189 192 186
-5 9 8 189 192 186
-4 9 8 189 192 186
-3 9 8 189 192 186
-2 9 8 189 192 186
-1 9 8 189 192 186
0 9 8 189 192 186
1 9 8 189 192 186
2 9 8 189 192 186
3 9 8 105 176 172
4 9 8 255 255 251
-16 10 8 189 192 186
-15 10 8 189 192 186
-14 10 8 189 192 186
-13 10 8 189 192 186
-12 10 8 189 192 186
-11 10 8 189 192 186
-10 10 8 189 192 186
-9 10 8 189 192 186
-8 10 8 189 192 186
-7 10 8 189 192 186
-6 10 8 189 192 186
-5 10 8 189 192 186
-4 10 8 189 192 186
-3 10 8 189 192 186
-2 10 8 189 192 186
-1 10 8 189 192 186
0 10 8 189 192 186
1 10 8 189 192 186
2 10 8 189 192 186
3 10 8 105 176 172
4 10 8 255 255 251
-16 11 8 189 192 186
-15 11 8 189 192 186
-14 11 8 189 192 186
-13 11 8 189 192 186
-12 11 8 189 192 186
-11 11 8 189 192 186
-10 11 8 189 192 186
-9 11 8 189 192 186
-8 11 8 189 192 186
-7 11 8 189 192 186
-6 11 8 189 192 186
-5 11 8 189 192 186
-4 11 8 189 192 186
-3 11 8 189 192 186
-2 11 8 189 192 186
-1 11 8 189 192 186
0 11 8 189 192 186
1 11 8 189 192 186
2 11 8 189 192 186
3 11 8 105 176 172
4 11 8 255 255 251
-16 12 8 189 192 186
-15 12 8 189 192 186
-14 12 8 189 192 186
-13 12 8 189 192 186
-12 12 8 189 192 186
-11 12 8 189 192 186
-10 12 8 189 192 186
-9 12 8 189 192 186
-8 12 8 189 192 186
-7 12 8 189 192 186
-6 12 8 189 192 186
-5 12 8 189 192 186
-4 12 8 189 192 186
-3 12 8 189 192 186
-2 12 8 189 192 186
-1 12 8 189 192 186
0 12 8 189 192 186
1 12 8 189 192 186
2 12 8 189 192 186
3 12 8 105 176 172
4 12 8 255 255 251
-16 13 8 189 192 186
-15 13 8 189 192 186
-14 13 8 189 192 186
-13 13 8 189 192 186
-12 13 8 189 192 186
-11 13 8 189 192 186
-10 13 8 189 192 186
-9 13 8 189 192 186
-8 13 8 189 192 186
-7 13 8 189 192 186
-6 13 8 189 192 186
-5 13 8 189 192 186
-4 13 8 189 192 186
-3 13 8 189 192 186
-2 13 8 189 192 186
-1 13 8 189 192 186
0 13 8 189 192 186
1 13 8 189 192 186
2 13 8 189 192 186
3 13 8 105 176 172
4 13 8 105 176 172
5 13 8 105 176 172
6 13 8 105 176 172
-16 14 8 189 192 186
-15 14 8 189 192 186
-14 14 8 189 192 186
-13 14 8 189 192 186
-12 14 8 189 192 186
-11 14 8 189 192 186
-10 14 8 189 192 186
-9 14 8 189 192 186
-8 14 8 189 192 186
-7 14 8 189 192 186
-6 14 8 189 192 186
-5 14 8 189 192 186
-4 14 8 189 192 186
-3 14 8 189 192 186
-2 14 8 189 192 186
-1 14 8 189 192 186
0 14 8 189 192 186
1 14 8 189 192 186
2 14 8 189 192 186
-16 15 8 189 192 186
-15 15 8 189 192 186
-14 15 8 189 192 186
-13 15 8 189 192 186
-12 15 8 189 192 186
-11 15 8 189 192 186
-10 15 8 189 192 186
-9 15 8 189 192 186
-8 15 8 189 192 186
-7 15 8 189 192 186
-6 15 8 189 192 186
-5 15 8 189 192 186
-4 15 8 189 192 186
-3 15 8 189 192 186
-2 15 8 189 192 186
-1 15 8 189 192 186
0 15 8 189 192 186
1 15 8 189 192 186
2 15 8 189 192 186
-16 16 8 189 192 186
-15 16 8 189 192 186
-14 16 8 189 192 186
-13 16 8 189 192 186
-12 16 8 189 192 186
-11 16 8 189 192 186
-10 16 8 189 192 186
-9 16 8 189 192 186
-8 16 8 189 192 186
-7 16 8 189 192 186
-6 16 8 189 192 186
-5 16 8 189 192 186
-4 16 8 189 192 186
-3 16 8 189 192 186
-2 16 8 189 192 186
-1 16 8 189 192 186
0 16 8 189 192 186
1 16 8 189 192 186
2 16 8 189 192 186
-16 17 8 189 192 186
-15 17 8 189 192 186
-14 17 8 189 192 186
-13 17 8 189 192 186
-12 17 8 189 192 186
-11 17 8 189 192 186
-10 17 8 189 192 186
-9 17 8 189 192 186
-8 17 8 189 192 186
-7 17 8 189 192 186
-6 17 8 189 192 186
-5 17 8 189 192 186
-4 17 8 189 192 186
-3 17 8 189 192 186
-2 17 8 189 192 186
-1 17 8 189 192 186
0 17 8 189 192 186
1 17 8 189 192 186
2 17 8 189 192 186
-16 18 8 189 192 186
-15 18 8 189 192 186
-14 18 8 189 192 186
-13 18 8 189 192 186
-12 18 8 189 192 186
-11 18 8 189 192 186
-10 18 8 189 192 186
-9 18 8 189 192 186
-8 18 8 189 192 186
-7 18 8 189 192 186
-6 18 8 189 192 186
-5 18 8 189 192 186
-4 18 8 189 192 186
-3 18 8 189 192 186
-2 18 8 189 192 186
-1 18 8 189 192 186
0 18 8 189 192 186
1 18 8 189 192 186
2 18 8 189 192 186
-16 19 8 189 192 186
-15 19 8 189 192 186
-14 19 8 189 192 186
-13 19 8 189 192 186
-12 19 8 189 192 186
-11 19 8 189 192 186
-10 19 8 189 192 186
-9 19 8 189 192 186
-8 19 8 189 192 186
-7 19 8 189 192 186
-6 19 8 189 192 186
-5 19 8 189 192 186
-4 19 8 189 192 186
-3 19 8 189 192 186
-2 19 8 189 192 186
-1 19 8 189 192 186
0 19 8 189 192 186
1 19 8 189 192 186
2 19 8 189 192 186
-16 -4 9 189 192 186
-15 -4 9 189 192 186
-16 -3 9 189 192 186
-15 -3 9 189 192 186
-16 -2 9 189 192 186
-15 -2 9 189 192 186
-16 -1 9 189 192 186
-15 -1 9 189 192 186
-16 0 9 189 192 186
-15 0 9 189 192 186
-16 1 9 189 192 186
-15 1 9 189 192 186
-14 1 9 189 192 186
-13 1 9 189 192 186
-12 1 9 189 192 186
-11 1 9 189 192 186
-10 1 9 189 192 186
-9 1 9 189 192 186
-8 1 9 189 192 186
-7 1 9 189 192 186
-6 1 9 189 192 186
-5 1 9 189 192 186
-4 1 9 189 192 186
-3 1 9 189 192 186
-2 1 9 189 192 186
-16 2 9 189 192 186
-15 2 9 189 192 186
-14 2 9 189 192 186
-13 2 9 189 192 186
-12 2 9 189 192 186
-11 2 9 189 192 186
-10 2 9 189 192 186
-9 2 9 189 192 186
-8 2 9 189 192 186
-7 2 9 189 192 186
-6 2 9 189 192 186
-5 2 9 189 192 186
-4 2 9 189 192 186
-3 2 9 189 192 186
-2 2 9 189 192 186
-16 3 9 189 192 186
-15 3 9 189 192 186
-14 3 9 189 192 186
-13 3 9 189 192 186
-12 3 9 189 192 186
-11 3 9 189 192 186
-10 3 9 189 192 186
-9 3 9 189 192 186
-8 3 9 189 192 186
-7 3 9 189 192 186
-6 3 9 189 192 186
-5 3 9 189 192 186
-4 3 9 189 192 186
-3 3 9 189 192 186
-2 3 9 189 192 186
-16 4 9 189 192 186
-15 4 9 189 192 186
-14 4 9 189 192 186
-13 4 9 189 192 186
-12 4 9 189 192 186
-11 4 9 189 192 186
-10 4 9 189 192 186
-9 4 9 189 192 186
-8 4 9 189 192 186
-7 4 9 189 192 186
-6 4 9 189 192 186
-5 4 9 189 192 186
-4 4 9 189 192 186
-3 4 9 189 192 186
-2 4 9 189 192 186
-16 5 9 189 192 186
-15 5 9 189 192 186
-14 5 9 189 192 186
-13 5 9 189 192 186
-12 5 9 189 192 186
-11 5 9 189 192 186
-10 5 9 189 192 186
-9 5 9 189 192 186
-8 5 9 189 192 186
-7 5 9 189 192 186
-6 5 9 189 192 186
-5 5 9 189 192 186
-4 5 9 189 192 186
-3 5 9 189 192 186
-2 5 9 189 192 186
-16 6 9 189 192 186
-15 6 9 189 192 186
-14 6 9 189 192 186
-13 6 9 189 192 186
-12 6 9 189 192 186
-11 6 9 189 192 186
-10 6 9 189 192 186
-9 6 9 189 192 186
-8 6 9 189 192 186
-7 6 9 189 192 186
-6 6 9 189 192 186
-5 6 9 189 192 186
-4 6 9 189 192 186
-3 6 9 189 192 186
-2 6 9 189 192 186
-1 6 9 189 192 186
0 6 9 189 192 186
1 6 9 189 192 186
2 6 9 189 192 186
-16 7 9 189 192 186
-15 7 9 189 192 186
-14 7 9 189 192 186
-13 7 9 189 192 186
-12 7 9 189 192 186
-11 7 9 189 192 186
-10 7 9 189 192 186
-9 7 9 189 192 186
-8 7 9 189 192 186
-7 7 9 189 192 186
-6 7 9 189 192 186
-5 7 9 189 192 186
-4 7 9 189 192 186
-3 7 9 189 192 186
-2 7 9 189 192 186
-1 7 9 189 192 186
0 7 9 189 192 186
1 7 9 189 192 186
2 7 9 189 192 186
3 7 9 105 176 172
4 7 9 105 176 172
5 7 9 105 176 172
6 7 9 105 176 172
-16 8 9 189 192 186
-15 8 9 189 192 186
-14 8 9 189 192 186
-13 8 9 189 192 186
-12 8 9 189 192 186
-11 8 9 189 192 186
-10 8 9 189 192 186
-9 8 9 189 192 186
-8 8 9 189 192 186
-7 8 9 189 192 186
-6 8 9 189 192 186
-5 8 9 189 192 186
-4 8 9 189 192 186
-3 8 9 189 192 186
-2 8 9 189 192 186
-1 8 9 189 192 186
0 8 9 189 192 186
1 8 9 189 192 186
2 8 9 189 192 186
3 8 9 105 176 172
4 8 9 105 176 172
5 8 9 145 152 159
-16 9 9 189 192 186
-15 9 9 189 192 186
-14 9 9 189 192 186
-13 9 9 189 192 186
-12 9 9 189 192 186
-11 9 9 189 192 186
-10 9 9 189 192 186
-9 9 9 189 192 186
-8 9 9 189 192 186
-7 9 9 189 192 186
-6 9 9 189 192 186
-5 9 9 189 192 186
-4 9 9 189 192 186
-3 9 9 189 192 186
-2 9 9 189 192 186
-1 9 9 189 192 186
0 9 9 189 192 186
1 9 9 189 192 186
2 9 9 189 192 186
3 9 9 105 176 172
4 9 9 105 176 172
5 9 9 145 152 159
-16 10 9 189 192 186
-15 10 9 189 192 186
-14 10 9 189 192 186
-13 10 9 189 192 186
-12 10 9 189 192 186
-11 10 9 189 192 186
-10 10 9 189 192 186
-9 10 9 189 192 186
-8 10 9 189 192 186
-7 10 9 189 192 186
-6 10 9 189 192 186
-5 10 9 189 192 186
-4 10 9 189 192 186
-3 10 9 189 192 186
-2 10 9 189 192 186
-1 10 9 189 192 186
0 10 9 189 192 186
1 10 9 189 192 186
2 10 9 189 192 186
3 10 9 105 176 172
4 10 9 105 176 172
5 10 9 145 152 159
-16 11 9 189 192 186
-15 11 9 189 192 186
-14 11 9 189 192 186
-13 11 9 189 192 186
-12 11 9 189 192 186
-11 11 9 189 192 186
-10 11 9 189 192 186
-9 11 9 189 192 186
-8 11 9 189 192 186
-7 11 9 189 192 186
-6 11 9 189 192 186
-5 11 9 189 192 186
-4 11 9 189 192 186
-3 11 9 189 192 186
-2 11 9 189 192 186
-1 11 9 189 192 186
0 11 9 189 192 186
1 11 9 189 192 186
2 11 9 189 192 186
3 11 9 105 176 172
4 11 9 105 176 172
5 11 9 145 152 159
-16 12 9 189 192 186
-15 12 9 189 192 186
-14 12 9 189 192 186
-13 12 9 189 192 186
-12 12 9 189 192 186
-11 12 9 189 192 186
-10 12 9 189 192 186
-9 12 9 189 192 186
-8 12 9 189 192 186
-7 12 9 189 192 186
-6 12 9 189 192 186
-5 12 9 189 192 186
-4 12 9 189 192 186
-3 12 9 189 192 186
-2 12 9 189 192 186
-1 12 9 189 192 186
0 12 9 189 192 186
1 12 9 189 192 186
2 12 9 189 192 186
3 12 9 105 176 172
4 12 9 105 176 172
5 12 9 145 152 159
-16 13 9 189 192 186
-15 13 9 189 192 186
-14 13 9 189 192 186
-13 13 9 189 192 186
-12 13 9 189 192 186
-11 13 9 189 192 186
-10 13 9 189 192 186
-9 13 9 189 192 186
-8 13 9 189 192 186
-7 13 9 189 192 186
-6 13 9 189 192 186
-5 13 9 189 192 186
-4 13 9 189 192 186
-3 13 9 189 192 186
-2 13 9 189 192 186
-1 13 9 189 192 186
0 13 9 189 192 186
1 13 9 189 192 186
2 13 9 189 192 186
3 13 9 105 176 172
4 13 9 105 176 172
5 13 9 105 176 172
6 13 9 105 176 172
-16 14 9 189 192 186
-15 14 9 189 192 186
-14 14 9 189 192 186
-13 14 9 189 192 186
-12 14 9 189 192 186
-11 14 9 189 192 186
-10 14 9 189 192 186
-9 14 9 189 192 186
-8 14 9 189 192 186
-7 14 9 189 192 186
-6 14 9 189 192 186
-5 14 9 189 192 186
-4 14 9 189 192 186
-3 14 9 189 192 186
-2 14 9 189 192 186
-1 14 9 189 192 186
0 14 9 189 192 186
1 14 9 189 192 186
2 14 9 189 192 186
-16 15 9 189 192 186
-15 15 9 189 192 186
-14 15 9 189 192 186
-13 15 9 189 192 186
-12 15 9 189 192 186
-11 15 9 189 192 186
-10 15 9 189 192 186
-9 15 9 189 192 186
-8 15 9 189 192 186
-7 15 9 189 192 186
-6 15 9 189 192 186
-5 15 9 189 192 186
-4 15 9 189 192 186
-3 15 9 189 192 186
-2 15 9 189 192 186
-1 15 9 189 192 186
0 15 9 189 192 186
1 15 9 189 192 186
2 15 9 189 192 186
-16 16 9 189 192 186
-15 16 9 189 192 186
-14 16 9 189 192 186
-13 16 9 189 192 186
-12 16 9 189 192 186
-11 16 9 189 192 186
-10 16 9 189 192 186
-9 16 9 189 192 186
-8 16 9 189 192 186
-7 16 9 189 192 186
-6 16 9 189 192 186
-5 16 9 189 192 186
-4 16 9 189 192 186
-3 16 9 189 192 186
-2 16 9 189 192 186
-1 16 9 189 192 186
0 16 9 189 192 186
1 16 9 189 192 186
2 16 9 189 192 186
-16 17 9 189 192 186
-15 17 9 189 192 186
-14 17 9 189 192 186
-13 17 9 189 192 186
-12 17 9 189 192 186
-11 17 9 189 192 186
-10 17 9 189 192 186
-9 17 9 189 192 186
-8 17 9 189 192 186
-7 17 9 189 192 186
-6 17 9 189 192 186
-5 17 9 189 192 186
-4 17 9 189 192 186
-3 17 9 189 192 186
-2 17 9 189 192 186
-1 17 9 189 192 186
0 17 9 189 192 186
1 17 9 189 192 186
2 17 9 189 192 186
-16 18 9 189 192 186
-15 18 9 189 192 186
-14 18 9 189 192 186
-13 18 9 189 192 186
-12 18 9 189 192 186
-11 18 9 189 192 186
-10 18 9 189 192 186
-9 18 9 189 192 186
-8 18 9 189 192 186
-7 18 9 189 192 186
-6 18 9 189 192 186
-5 18 9 189 192 186
-4 18 9 189 192 186
-3 18 9 189 192 186
-2 18 9 189 192 186
-1 18 9 189 192 186
0 18 9 189 192 186
1 18 9 189 192 186
2 18 9 189 192 186
-16 19 9 189 192 186
-15 19 9 189 192 186
-14 19 9 189 192 186
-13 19 9 189 192 186
-12 19 9 189 192 186
-11 19 9 189 192 186
-10 19 9 189 192 186
-9 19 9 189 192 186
-8 19 9 189 192 186
-7 19 9 189 192 186
-6 19 9 189 192 186
-5 19 9 189 192 186
-4 19 9 189 192 186
-3 19 9 189 192 186
-2 19 9 189 192 186
-1 19 9 189 192 186
0 19 9 189 192 186
1 19 9 189 192 186
2 19 9 189 192 186
-16 -4 10 189 192 186
-15 -4 10 189 192 186
-14 -4 10 189 192 186
-13 -4 10 189 192 186
-12 -4 10 189 192 186
-11 -4 10 189 192 186
-10 -4 10 189 192 186
-9 -4 10 189 192 186
-8 -4 10 189 192 186
-7 -4 10 189 192 186
-6 -4 10 189 192 186
-5 -4 10 189 192 186
-4 -4 10 189 192 186
-3 -4 10 189 192 186
-2 -4 10 189 192 186
-1 -4 10 189 192 186
0 -4 10 189 192 186
1 -4 10 189 192 186
2 -4 10 189 192 186
-16 -3 10 189 192 186
-15 -3 10 189 192 186
-14 -3 10 189 192 186
-13 -3 10 189 192 186
-12 -3 10 189 192 186
-11 -3 10 189 192 186
-10 -3 10 189 192 186
-9 -3 10 189 192 186
-8 -3 10 189 192 186
-7 -3 10 189 192 186
-6 -3 10 189 192 186
-5 -3 10 189 192 186
-4 -3 10 189 192 186
-3 -3 10 189 192 186
-2 -3 10 189 192 186
-1 -3 10 189 192 186
0 -3 10 189 192 186
1 -3 10 189 192 186
2 -3 10 189 192 186
-16 -2 10 189 192 186
-15 -2 10 189 192 186
-14 -2 10 189 192 186
-13 -2 10 189 192 186
-12 -2 10 189 192 186
-11 -2 10 189 192 186
-10 -2 10 189 192 186
-9 -2 10 189 192 186
-8 -2 10 189 192 186
-7 -2 10 189 192 186
-6 -2 10 189 192 186
-5 -2 10 189 192 186
-4 -2 10 189 192 186
-3 -2 10 189 192 186
-2 -2 10 189 192 186
-1 -2 10 189 192 186
0 -2 10 189 192 186
1 -2 10 189 192 186
2 -2 10 189 192 186
-16 -1 10 189 192 186
-15 -1 10 189 192 186
-14 -1 10 189 192 186
-13 -1 10 189 192 186
-12 -1 10 189 192 186
-11 -1 10 189 192 186
-10 -1 10 189 192 186
-9 -1 10 189 192 186
-8 -1 10 189 192 186
-7 -1 10 189 192 186
-6 -1 10 189 192 186
-5 -1 10 189 192 186
-4 -1 10 189 192 186
-3 -1 10 189 192 186
-2 -1 10 189 192 186
-1 -1 10 189 192 186
0 -1 10 189 192 186
1 -1 10 189 192 186
2 -1 10 189 192 186
-16 0 10 189 192 186
-15 0 10 189 192 186
-14 0 10 189 192 186
-13 0 10 189 192 186
-12 0 10 189 192 186
-11 0 10 189 192 186
-10 0 10 189 192 186
-9 0 10 189 192 186
-8 0 10 189 192 186
-7 0 10 189 192 186
-6 0 10 189 192 186
-5 0 10 189 192 186
-4 0 10 189 192 186
-3 0 10 189 192 186
-2 0 10 189 192 186
-1 0 10 189 192 186
0 0 10 189 192 186
1 0 10 189 192 186
2 0 10 189 192 186
-16 1 10 189 192 186
-15 1 10 189 192 186
-14 1 10 189 192 186
-13 1 10 189 192 186
-12 1 10 189 192 186
-11 1 10 189 192 186
-10 1 10 189 192 186
-9 1 10 189 192 186
-8 1 10 189 192 186
-7 1 10 189 192 186
-6 1 10 189 192 186
-5 1 10 189 192 186
-4 1 10 189 192 186
-3 1 10 189 192 186
-2 1 10 189 192 186
-1 1 10 189 192 186
0 1 10 189 192 186
1 1 10 189 192 186
2 1 10 189 192 186
-16 2 10 189 192 186
-15 2 10 189 192 186
-14 2 10 189 192 186
-13 2 10 189 192 186
-12 2 10 189 192 186
-11 2 10 189 192 186
-10 2 10 189 192 186
-9 2 10 189 192 186
-8 2 10 189 192 186
-7 2 10 189 192 186
-6 2 10 189 192 186
-5 2 10 189 192 186
-4 2 10 189 192 186
-3 2 10 189 192 186
-2 2 10 189 192 186
-1 2 10 189 192 186
0 2 10 189 192 186
1 2 10 189 192 186
2 2 10 189 192 186
-16 3 10 189 192 186
-15 3 10 189 192 186
-14 3 10 189 192 186
-13 3 10 189 192 186
-12 3 10 189 192 186
-11 3 10 189 192 186
-10 3 10 189 192 186
-9 3 10 189 192 186
-8 3 10 189 192 186
-7 3 10 189 192 186
-6 3 10 189 192 186
-5 3 10 189 192 186
-4 3 10 189 192 186
-3 3 10 189 192 186
-2 3 10 189 192 186
-1 3 10 189 192 186
0 3 10 189 192 186
1 3 10 189 192 186
2 3 10 189 192 186
-16 4 10 189 192 186
-15 4 10 189 192 186
-14 4 10 189 192 186
-13 4 10 189 192 186
-12 4 10 189 192 186
-11 4 10 189 192 186
-10 4 10 189 192 186
-9 4 10 189 192 186
-8 4 10 189 192 186
-7 4 10 189 192 186
-6 4 10 189 192 186
-5 4 10 189 192 186
-4 4 10 189 192 186
-3 4 10 189 192 186
-2 4 10 189 192 186
-1 4 10 189 192 186
0 4 10 189 192 186
1 4 10 189 192 186
2 4 10 189 192 186
-16 5 10 189 192 186
-15 5 10 189 192 186
-14 5 10 189 192 186
-13 5 10 189 192 186
-12 5 10 189 192 186
-11 5 10 189 192 186
-10 5 10 189 192 186
-9 5 10 189 192 186
-8 5 10 189 192 186
-7 5 10 189 192 186
-6 5 10 189 192 186
-5 5 10 189 192 186
-4 5 10 189 192 186
-3 5 10 189 192 186
-2 5 10 189 192 186
-1 5 10 189 192 186
0 5 10 189 192 186
1 5 10 189 192 186
2 5 10 189 192 186
-16 6 10 189 192 186
-15 6 10 189 192 186
-14 6 10 189 192 186
-13 6 10 189 192 186
-12 6 10 189 192 186
-11 6 10 189 192 186
-10 6 10 189 192 186
-9 6 10 189 192 186
-8 6 10 189 192 186
-7 6 10 189 192 186
-6 6 10 189 192 186
-5 6 10 189 192 186
-4 6 10 189 192 186
-3 6 10 189 192 186
-2 6 10 189 192 186
-1 6 10 189 192 186
0 6 10 189 192 186
1 6 10 189 192 186
2 6 10 189 192 186
-16 7 10 189 192 186
-15 7 10 189 192 186
-14 7 10 189 192 186
-13 7 10 189 192 186
-12 7 10 189 192 186
-11 7 10 189 192 186
-10 7 10 189 192 186
-9 7 10 189 192 186
-8 7 10 189 192 186
-7 7 10 189 192 186
-6 7 10 189 192 186
-5 7 10 189 192 186
-4 7 10 189 192 186
-3 7 10 189 192 186
-2 7 10 189 192 186
-1 7 10 189 192 186
0 7 10 189 192 186
1 7 10 189 192 186
2 7 10 189 192 186
3 7 10 105 176 172
4 7 10 105 176 172
5 7 10 105 176 172
6 7 10 105 176 172
-16 8 10 189 192 186
-15 8 10 189 192 186
-14 8 10 189 192 186
-13 8 10 189 192 186
-12 8 10 189 192 186
-11 8 10 189 192 186
-10 8 10 189 192 186
-9 8 10 189 192 186
-8 8 10 189 192 186
-7 8 10 189 192 186
-6 8 10 189 192 186
-5 8 10 189 192 186
-4 8 10 189 192 186
-3 8 10 189 192 186
-2 8 10 189 192 186
-1 8 10 189 192 186
0 8 10 189 192 186
1 8 10 189 192 186
2 8 10 189 192 186
3 8 10 105 176 172
4 8 10 255 255 251
-16 9 10 189 192 186
-15 9 10 189 192 186
-14 9 10 189 192 186
-13 9 10 189 192 186
-12 9 10 189 192 186
-11 9 10 189 192 186
-10 9 10 189 192 186
-9 9 10 189 192 186
-8 9 10 189 192 186
-7 9 10 189 192 186
-6 9 10 189 192 186
-5 9 10 189 192 186
-4 9 10 189 192 186
-3 9 10 189 192 186
-2 9 10 189 192 186
-1 9 10 189 192 186
0 9 10 189 192 186
1 9 10 189 192 186
2 9 10 189 192 186
3 9 10 105 176 172
4 9 10 105 176 172
5 9 10 193 138 38
-16 10 10 189 192 186
-15 10 10 189 192 186
-14 10 10 189 192 186
-13 10 10 189 192 186
-12 10 10 189 192 186
-11 10 10 189 192 186
-10 10 10 189 192 186
-9 10 10 189 192 186
-8 10 10 189 192 186
-7 10 10 189 192 186
-6 10 10 189 192 186
-5 10 10 189 192 186
-4 10 10 189 192 186
-3 10 10 189 192 186
-2 10 10 189 192 186
-1 10 10 189 192 186
0 10 10 189 192 186
1 10 10 189 192 186
2 10 10 189 192 186
3 10 10 105 176 172
4 10 10 255 255 251
-16 11 10 189 192 186
-15 11 10 189 192 186
-14 11 10 189 192 186
-13 11 10 189 192 186
-12 11 10 189 192 186
-11 11 10 189 192 186
-10 11 10 189 192 186
-9 11 10 189 192 186
-8 11 10 189 192 186
-7 11 10 189 192 186
-6 11 10 189 192 186
-5 11 10 189 192 186
-4 11 10 189 192 186
-3 11 10 189 192 186
-2 11 10 189 192 186
-1 11 10 189 192 186
0 11 10 189 192 186
1 11 10 189 192 186
2 11 10 189 192 186
3 11 10 105 176 172
4 11 10 105 176 172
5 11 10 224 60 138
-16 12 10 189 192 186
-15 12 10 189 192 186
-14 12 10 189 192 186
-13 12 10 189 192 186
-12 12 10 189 192 186
-11 12 10 189 192 186
-10 12 10 189 192 186
-9 12 10 189 192 186
-8 12 10 189 192 186
-7 12 10 189 192 186
-6 12 10 189 192 186
-5 12 10 189 192 186
-4 12 10 189 192 186
-3 12 10 189 192 186
-2 12 10 189 192 186
-1 12 10 189 192 186
0 12 10 189 192 186
1 12 10 189 192 186
2 12 10 189 192 186
3 12 10 105 176 172
4 12 10 255 255 251
-16 13 10 189 192 186
-15 13 10 189 192 186
-14 13 10 189 192 186
-13 13 10 189 192 186
-12 13 10 189 192 186
-11 13 10 189 192 186
-10 13 10 189 192 186
-9 13 10 189 192 186
-8 13 10 189 192 186
-7 13 10 189 192 186
-6 13 10 189 192 186
-5 13 10 189 192 186
-4 13 10 189 192 186
-3 13 10 189 192 186
-2 13 10 189 192 186
-1 13 10 189 192 186
0 13 10 189 192 186
1 13 10 189 192 186
2 13 10 189 192 186
3 13 10 105 176 172
4 13 10 105 176 172
5 13 10 105 176 172
6 13 10 105 176 172
-16 14 10 189 192 186
-15 14 10 189 192 186
-14 14 10 189 192 186
-13 14 10 189 192 186
-12 14 10 189 192 186
-11 14 10 189 192 186
-10 14 10 189 192 186
-9 14 10 189 192 186
-8 14 10 189 192 186
-7 14 10 189 192 186
-6 14 10 189 192 186
-5 14 10 189 192 186
-4 14 10 189 192 186
-3 14 10 189 192 186
-2 14 10 189 192 186
-1 14 10 189 192 186
0 14 10 189 192 186
1 14 10 189 192 186
2 14 10 189 192 186
-16 15 10 189 192 186
-15 15 10 189 192 186
-14 15 10 189 192 186
-13 15 10 189 192 186
-12 15 10 189 192 186
-11 15 10 189 192 186
-10 15 10 189 192 186
-9 15 10 189 192 186
-8 15 10 189 192 186
-7 15 10 189 192 186
-6 15 10 189 192 186
-5 15 10 189 192 186
-4 15 10 189 192 186
-3 15 10 189 192 186
-2 15 10 189 192 186
-1 15 10 189 192 186
0 15 10 189 192 186
1 15 10 189 192 186
2 15 10 189 192 186
-16 16 10 189 192 186
-15 16 10 189 192 186
-14 16 10 189 192 186
-13 16 10 189 192 186
-12 16 10 189 192 186
-11 16 10 189 192 186
-10 16 10 189 192 186
-9 16 10 189 192 186
-8 16 10 189 192 186
-7 16 10 189 192 186
-6 16 10 189 192 186
-5 16 10 189 192 186
-4 16 10 189 192 186
-3 16 10 189 192 186
-2 16 10 189 192 186
-1 16 10 189 192 186
0 16 10 189 192 186
1 16 10 189 192 186
2 16 10 189 192 186
-16 17 10 189 192 186
-15 17 10 189 192 186
-14 17 10 189 192 186
-13 17 10 189 192 186
-12 17 10 189 192 186
-11 17 10 189 192 186
-10 17 10 189 192 186
-9 17 10 189 192 186
-8 17 10 189 192 186
-7 17 10 189 192 186
-6 17 10 189 192 186
-5 17 10 189 192 186
-4 17 10 189 192 186
-3 17 10 189 192 186
-2 17 10 189 192 186
-1 17 10 189 192 186
0 17 10 189 192 186
1 17 10 189 192 186
2 17 10 189 192 186
-16 18 10 189 192 186
-15 18 10 189 192 186
-14 18 10 189 192 186
-13 18 10 189 192 186
-12 18 10 189 192 186
-11 18 10 189 192 186
-10 18 10 189 192 186
-9 18 10 189 192 186
-8 18 10 189 192 186
-7 18 10 189 192 186
-6 18 10 189 192 186
-5 18 10 189 192 186
-4 18 10 189 192 186
-3 18 10 189 192 186
-2 18 10 189 192 186
-1 18 10 189 192 186
0 18 10 189 192 186
1 18 10 189 192 186
2 18 10 189 192 186
-16 19 10 189 192 186
-15 19 10 189 192 186
-14 19 10 189 192 186
-13 19 10 189 192 186
-12 19 10 189 192 186
-11 19 10 189 192 186
-10 19 10 189 192 186
-9 19 10 189 192 186
-8 19 10 189 192 186
-7 19 10 189 192 186
-6 19 10 189 192 186
-5 19 10 189 192 186
-4 19 10 189 192 186
-3 19 10 189 192 186
-2 19 10 189 192 186
-1 19 10 189 192 186
0 19 10 189 192 186
1 19 10 189 192 186
2 19 10 189 192 186
-13 -9 11 232 48 21
-12 -9 11 219 142 113
-11 -9 11 232 48 21
-10 -9 11 219 142 113
-9 -9 11 232 48 21
-8 -9 11 219 142 113
-7 -9 11 232 48 21
-6 -9 11 219 142 113
-5 -9 11 232 48 21
-4 -9 11 219 142 113
-3 -9 11 232 48 21
-2 -9 11 219 142 113
-1 -9 11 232 48 21
-13 -8 11 232 48 21
-12 -8 11 219 142 113
-11 -8 11 232 48 21
-10 -8 11 219 142 113
-9 -8 11 232 48 21
-8 -8 11 219 142 113
-7 -8 11 232 48 21
-6 -8 11 219 142 113
-5 -8 11 232 48 21
-4 -8 11 219 142 113
-3 -8 11 232 48 21
-2 -8 11 219 142 113
-1 -8 11 232 48 21
-13 -7 11 232 48 21
-12 -7 11 219 142 113
-11 -7 11 232 48 21
-10 -7 11 219 142 113
-9 -7 11 232 48 21
-8 -7 11 219 142 113
-7 -7 11 232 48 21
-6 -7 11 219 142 113
-5 -7 11 232 48 21
-4 -7 11 219 142 113
-3 -7 11 232 48 21
-2 -7 11 219 142 113
-1 -7 11 232 48 21
-13 -6 11 232 48 21
-12 -6 11 219 142 113
-11 -6 11 232 48 21
-10 -6 11 219 142 113
-9 -6 11 232 48 21
-8 -6 11 219 142 113
-7 -6 11 232 48 21
-6 -6 11 219 142 113
-5 -6 11 232 48 21
-4 -6 11 219 142 113
-3 -6 11 232 48 21
-2 -6 11 219 142 113
-1 -6 11 232 48 21
-13 -5 11 232 48 21
-12 -5 11 219 142 113
-11 -5 11 232 48 21
-10 -5 11 219 142 113
-9 -5 11 232 48 21
-8 -5 11 219 142 113
-7 -5 11 232 48 21
-6 -5 11 219 142 113
-5 -5 11 232 48 21
-4 -5 11 219 142 113
-3 -5 11 232 48 21
-2 -5 11 219 142 113
-1 -5 11 232 48 21
-16 -4 11 189 192 186
-15 -4 11 189 192 186
-14 -4 11 189 192 186
-13 -4 11 189 192 186
-12 -4 11 189 192 186
-11 -4 11 189 192 186
-10 -4 11 189 192 186
-9 -4 11 189 192 186
-8 -4 11 189 192 186
-7 -4 11 189 192 186
-6 -4 11 189 192 186
-5 -4 11 189 192 186
-4 -4 11 189 192 186
-3 -4 11 189 192 186
-2 -4 11 189 192 186
-1 -4 11 189 192 186
0 -4 11 189 192 186
1 -4 11 189 192 186
2 -4 11 189 192 186
-16 -3 11 189 192 186
-15 -3 11 189 192 186
-14 -3 11 189 192 186
-13 -3 11 189 192 186
-12 -3 11 189 192 186
-11 -3 11 189 192 186
-10 -3 11 189 192 186
-9 -3 11 189 192 186
-8 -3 11 189 192 186
-7 -3 11 189 192 186
-6 -3 11 189 192 186
-5 -3 11 189 192 186
-4 -3 11 189 192 186
-3 -3 11 189 192 186
-2 -3 11 189 192 186
-1 -3 11 189 192 186
0 -3 11 189 192 186
1 -3 11 189 192 186
2 -3 11 189 192 186
-16 -2 11 189 192 186
-15 -2 11 189 192 186
-14 -2 11 189 192 186
-13 -2 11 189 192 186
-12 -2 11 189 192 186
-11 -2 11 189 192 186
-10 -2 11 189 192 186
-9 -2 11 189 192 186
-8 -2 11 189 192 186
-7 -2 11 189 192 186
-6 -2 11 189 192 186
-5 -2 11 189 192 186
-4 -2 11 189 192 186
-3 -2 11 189 192 186
-2 -2 11 189 192 186
-1 -2 11 189 192 186
0 -2 11 189 192 186
1 -2 11 189 192 186
2 -2 11 189 192 186
-16 -1 11 189 192 186
-15 -1 11 189 192 186
-14 -1 11 189 192 186
-13 -1 11 189 192 186
-12 -1 11 189 192 186
-11 -1 11 189 192 186
-10 -1 11 189 192 186
-9 -1 11 189 192 186
-8 -1 11 189 192 186
-7 -1 11 189 192 186
-6 -1 11 189 192 186
-5 -1 11 189 192 186
-4 -1 11 189 192 186
-3 -1 11 189 192 186
-2 -1 11 189 192 186
-1 -1 11 189 192 186
0 -1 11 189 192 186
1 -1 11 189 192 186
2 -1 11 189 192 186
-16 0 11 189 192 186
-15 0 11 189 192 186
-14 0 11 189 192 186
-13 0 11 189 192 186
-12 0 11 189 192 186
-11 0 11 189 192 186
-10 0 11 189 192 186
-9 0 11 189 192 186
-8 0 11 189 192 186
-7 0 11 189 192 186
-6 0 11 189 192 186
-5 0 11 189 192 186
-4 0 11 189 192 186
-3 0 11 189 192 186
-2 0 11 189 192 186
-1 0 11 189 192 186
0 0 11 189 192 186
1 0 11 189 192 186
2 0 11 189 192 186
-16 1 11 189 192 186
-15 1 11 189 192 186
-14 1 11 189 192 186
-13 1 11 189 192 186
-12 1 11 189 192 186
-11 1 11 189 192 186
-10 1 11 189 192 186
-9 1 11 189 192 186
-8 1 11 189 192 186
-7 1 11 189 192 186
-6 1 11 189 192 186
-5 1 11 189 192 186
-4 1 11 189 192 186
-3 1 11 189 192 186
-2 1 11 189 192 186
-1 1 11 189 192 186
0 1 11 189 192 186
1 1 11 189 192 186
2 1 11 189 192 186
-16 2 11 189 192 186
-15 2 11 189 192 186
-14 2 11 189 192 186
-13 2 11 189 192 186
-12 2 11 189 192 186
-11 2 11 189 192 186
-10 2 11 189 192 186
-9 2 11 189 192 186
-8 2 11 189 192 186
-7 2 11 189 192 186
-6 2 11 189 192 186
-5 2 11 189 192 186
-4 2 11 189 192 186
-3 2 11 189 192 186
-2 2 11 189 192 186
-1 2 11 189 192 186
0 2 11 189 192 186
1 2 11 189 192 186
2 2 11 189 192 186
-16 3 11 189 192 186
-15 3 11 189 192 186
-14 3 11 189 192 186
-13 3 11 189 192 186
-12 3 11 189 192 186
-11 3 11 189 192 186
-10 3 11 189 192 186
-9 3 11 189 192 186
-8 3 11 189 192 186
-7 3 11 189 192 186
-6 3 11 189 192 186
-5 3 11 189 192 186
-4 3 11 189 192 186
-3 3 11 189 192 186
-2 3 11 189 192 186
-1 3 11 189 192 186
0 3 11 189 192 186
1 3 11 189 192 186
2 3 11 189 192 186
-16 4 11 189 192 186
-15 4 11 189 192 186
-14 4 11 189 192 186
-13 4 11 189 192 186
-12 4 11 189 192 186
-11 4 11 189 192 186
-10 4 11 189 192 186
-9 4 11 189 192 186
-8 4 11 189 192 186
-7 4 11 189 192 186
-6 4 11 189 192 186
-5 4 11 189 192 186
-4 4 11 189 192 186
-3 4 11 189 192 186
-2 4 11 189 192 186
-1 4 11 189 192 186
0 4 11 189 192 186
1 4 11 189 192 186
2 4 11 189 192 186
-16 5 11 189 192 186
-15 5 11 189 192 186
-14 5 11 189 192 186
-13 5 11 189 192 186
-12 5 11 189 192 186
-11 5 11 189 192 186
-10 5 11 189 192 186
-9 5 11 189 192 186
-8 5 11 189 192 186
-7 5 11 189 192 186
-6 5 11 189 192 186
-5 5 11 189 192 186
-4 5 11 189 192 186
-3 5 11 189 192 186
-2 5 11 189 192 186
-1 5 11 189 192 186
0 5 11 189 192 186
1 5 11 189 192 186
2 5 11 189 192 186
-16 6 11 189 192 186
-15 6 11 189 192 186
-14 6 11 189 192 186
-13 6 11 189 192 186
-12 6 11 189 192 186
-11 6 11 189 192 186
-10 6 11 189 192 186
-9 6 11 189 192 186
-8 6 11 189 192 186
-7 6 11 189 192 186
-6 6 11 189 192 186
-5 6 11 189 192 186
-4 6 11 189 192 186
-3 6 11 189 192 186
-2 6 11 189 192 186
-1 6 11 189 192 186
0 6 11 189 192 186
1 6 11 189 192 186
2 6 11 189 192 186
-16 7 11 189 192 186
-15 7 11 189 192 186
-14 7 11 189 192 186
-13 7 11 189 192 186
-12 7 11 189 192 186
-11 7 11 189 192 186
-10 7 11 189 192 186
-9 7 11 189 192 186
-8 7 11 189 192 186
-7 7 11 189 192 186
-6 7 11 189 192 186
-5 7 11 189 192 186
-4 7 11 189 192 186
-3 7 11 189 192 186
-2 7 11 189 192 186
-1 7 11 189 192 186
0 7 11 189 192 186
1 7 11 189 192 186
2 7 11 189 192 186
3 7 11 105 176 172
4 7 11 105 176 172
5 7 11 105 176 172
6 7 11 105 176 172
-16 8 11 189 192 186
-15 8 11 189 192 186
-14 8 11 189 192 186
-13 8 11 189 192 186
-12 8 11 189 192 186
-11 8 11 189 192 186
-10 8 11 189 192 186
-9 8 11 189 192 186
-8 8 11 189 192 186
-7 8 11 189 192 186
-6 8 11 189 192 186
-5 8 11 189 192 186
-4 8 11 189 192 186
-3 8 11 189 192 186
-2 8 11 189 192 186
-1 8 11 189 192 186
0 8 11 189 192 186
1 8 11 189 192 186
2 8 11 189 192 186
3 8 11 105 176 172
4 8 11 255 255 251
-16 9 11 189 192 186
-15 9 11 189 192 186
-14 9 11 189 192 186
-13 9 11 189 192 186
-12 9 11 189 192 186
-11 9 11 189 192 186
-10 9 11 189 192 186
-9 9 11 189 192 186
-8 9 11 189 192 186
-7 9 11 189 192 186
-6 9 11 189 192 186
-5 9 11 189 192 186
-4 9 11 189 192 186
-3 9 11 189 192 186
-2 9 11 189 192 186
-1 9 11 189 192 186
0 9 11 189 192 186
1 9 11 189 192 186
2 9 11 189 192 186
3 9 11 105 176 172
4 9 11 255 255 251
-16 10 11 189 192 186
-15 10 11 189 192 186
-14 10 11 189 192 186
-13 10 11 189 192 186
-12 10 11 189 192 186
-11 10 11 189 192 186
-10 10 11 189 192 186
-9 10 11 189 192 186
-8 10 11 189 192 186
-7 10 11 189 192 186
-6 10 11 189 192 186
-5 10 11 189 192 186
-4 10 11 189 192 186
-3 10 11 189 192 186
-2 10 11 189 192 186
-1 10 11 189 192 186
0 10 11 189 192 186
1 10 11 189 192 186
2 10 11 189 192 186
3 10 11 105 176 172
4 10 11 255 255 251
-16 11 11 189 192 186
-15 11 11 189 192 186
-14 11 11 189 192 186
-13 11 11 189 192 186
-12 11 11 189 192 186
-11 11 11 189 192 186
-10 11 11 189 192 186
-9 11 11 189 192 186
-8 11 11 189 192 186
-7 11 11 189 192 186
-6 11 11 189 192 186
-5 11 11 189 192 186
-4 11 11 189 192 186
-3 11 11 189 192 186
-2 11 11 189 192 186
-1 11 11 189 192 186
0 11 11 189 192 186
1 11 11 189 192 186
2 11 11 189 192 186
3 11 11 105 176 172
4 11 11 255 255 251
-16 12 11 189 192 186
-15 12 11 189 192 186
-14 12 11 189 192 186
-13 12 11 189 192 186
-12 12 11 189 192 186
-11 12 11 189 192 186
-10 12 11 189 192 186
-9 12 11 189 192 186
-8 12 11 189 192 186
-7 12 11 189 192 186
-6 12 11 189 192 186
-5 12 11 189 192 186
-4 12 11 189 192 186
-3 12 11 189 192 186
-2 12 11 189 192 186
-1 12 11 189 192 186
0 12 11 189 192 186
1 12 11 189 192 186
2 12 11 189 192 186
3 12 11 105 176 172
4 12 11 255 255 251
-16 13 11 189 192 186
-15 13 11 189 192 186
-14 13 11 189 192 186
-13 13 11 189 192 186
-12 13 11 189 192 186
-11 13 11 189 192 186
-10 13 11 189 192 186
-9 13 11 189 192 186
-8 13 11 189 192 186
-7 13 11 189 192 186
-6 13 11 189 192 186
-5 13 11 189 192 186
-4 13 11 189 192 186
-3 13 11 189 192 186
-2 13 11 189 192 186
-1 13 11 189 192 186
0 13 11 189 192 186
1 13 11 189 192 186
2 13 11 189 192 186
3 13 11 105 176 172
4 13 11 105 176 172
5 13 11 105 176 172
6 13 11 105 176 172
-16 14 11 189 192 186
-15 14 11 189 192 186
-14 14 11 189 192 186
-13 14 11 189 192 186
-12 14 11 189 192 186
-11 14 11 189 192 186
-10 14 11 189 192 186
-9 14 11 189 192 186
-8 14 11 189 192 186
-7 14 11 189 192 186
-6 14 11 189 192 186
-5 14 11 189 192 186
-4 14 11 189 192 186
-3 14 11 189 192 186
-2 14 11 189 192 186
-1 14 11 189 192 186
0 14 11 189 192 186
1 14 11 189 192 186
2 14 11 189 192 186
-16 15 11 189 192 186
-15 15 11 189 192 186
-14 15 11 189 192 186
-13 15 11 189 192 186
-12 15 11 189 192 186
-11 15 11 189 192 186
-10 15 11 189 192 186
-9 15 11 189 192 186
-8 15 11 189 192 186
-7 15 11 189 192 186
-6 15 11 189 192 186
-5 15 11 189 192 186
-4 15 11 189 192 186
-3 15 11 189 192 186
-2 15 11 189 192 186
-1 15 11 189 192 186
0 15 11 189 192 186
1 15 11 189 192 186
2 15 11 189 192 186
-16 16 11 189 192 186
-15 16 11 189 192 186
-14 16 11 189 192 186
-13 16 11 189 192 186
-12 16 11 189 192 186
-11 16 11 189 192 186
-10 16 11 189 192 186
-9 16 11 189 192 186
-8 16 11 189 192 186
-7 16 11 189 192 186
-6 16 11 189 192 186
-5 16 11 189 192 186
-4 16 11 189 192 186
-3 16 11 189 192 186
-2 16 11 189 192 186
-1 16 11 189 192 186
0 16 11 189 192 186
1 16 11 189 192 186
2 16 11 189 192 186
-16 17 11 189 192 186
-15 17 11 189 192 186
-14 17 11 189 192 186
-13 17 11 189 192 186
-12 17 11 189 192 186
-11 17 11 189 192 186
-10 17 11 189 192 186
-9 17 11 189 192 186
-8 17 11 189 192 186
-7 17 11 189 192 186
-6 17 11 189 192 186
-5 17 11 189 192 186
-4 17 11 189 192 186
-3 17 11 189 192 186
-2 17 11 189 192 186
-1 17 11 189 192 186
0 17 11 189 192 186
1 17 11 189 192 186
2 17 11 189 192 186
-16 18 11 189 192 186
-15 18 11 189 192 186
-14 18 11 189 192 186
-13 18 11 189 192 186
-12 18 11 189 192 186
-11 18 11 189 192 186
-10 18 11 189 192 186
-9 18 11 189 192 186
-8 18 11 189 192 186
-7 18 11 189 192 186
-6 18 11 189 192 186
-5 18 11 189 192 186
-4 18 11 189 192 186
-3 18 11 189 192 186
-2 18 11 189 192 186
-1 18 11 189 192 186
0 18 11 189 192 186
1 18 11 189 192 186
2 18 11 189 192 186
-16 19 11 189 192 186
-15 19 11 189 192 186
-14 19 11 189 192 186
-13 19 11 189 192 186
-12 19 11 189 192 186
-11 19 11 189 192 186
-10 19 11 189 192 186
-9 19 11 189 192 186
-8 19 11 189 192 186
-7 19 11 189 192 186
-6 19 11 189 192 186
-5 19 11 189 192 186
-4 19 11 189 192 186
-3 19 11 189 192 186
-2 19 11 189 192 186
-1 19 11 189 192 186
0 19 11 189 192 186
1 19 11 189 192 186
2 19 11 189 192 186
-16 -4 12 189 192 186
-15 -4 12 189 192 186
-14 -4 12 189 192 186
-13 -4 12 189 192 186
-12 -4 12 189 192 186
-11 -4 12 189 192 186
-10 -4 12 189 192 186
-9 -4 12 189 192 186
-8 -4 12 189 192 186
-7 -4 12 189 192 186
-6 -4 12 189 192 186
-5 -4 12 189 192 186
-4 -4 12 189 192 186
-3 -4 12 189 192 186
-2 -4 12 189 192 186
-1 -4 12 189 192 186
0 -4 12 189 192 186
1 -4 12 189 192 186
2 -4 12 189 192 186
-16 -3 12 189 192 186
-15 -3 12 189 192 186
-14 -3 12 189 192 186
-13 -3 12 189 192 186
-12 -3 12 189 192 186
-11 -3 12 189 192 186
-10 -3 12 189 192 186
-9 -3 12 189 192 186
-8 -3 12 189 192 186
-7 -3 12 189 192 186
-6 -3 12 189 192 186
-5 -3 12 189 192 186
-4 -3 12 189 192 186
-3 -3 12 189 192 186
-2 -3 12 189 192 186
-1 -3 12 189 192 186
0 -3 12 189 192 186
1 -3 12 189 192 186
2 -3 12 189 192 186
-16 -2 12 189 192 186
-15 -2 12 189 192 186
-14 -2 12 189 192 186
-13 -2 12 189 192 186
-12 -2 12 189 192 186
-11 -2 12 189 192 186
-10 -2 12 189 192 186
-9 -2 12 189 192 186
-8 -2 12 189 192 186
-7 -2 12 189 192 186
-6 -2 12 189 192 186
-5 -2 12 189 192 186
-4 -2 12 189 192 186
-3 -2 12 189 192 186
-2 -2 12 189 192 186
